Workbook

Sheet Sizing Tool
A1: GPU Memory Sizing — Training a Transformer on a Single GPU
A2: Companion tool to Article 1, "Training: The Four Line Items of GPU Memory." Fill in the blue cells. Everything else calculates.
A3: LEGEND: blue text = you edit these | yellow fill = assumption you may override | black text = calculated, do not edit | green text = pulled from another tab. The workbook opens pre-filled with the exact configuration benchmarked in Article 1, as a worked example.
A5: STEP 1 — YOUR MODEL
A6: Model size | B6: Article 1 worked model (1.0B) | C6: Pick from the dropdown. This is the only model input most people need.
A8: Architecture | C8: From preset | D8: Your override (optional) | E8: Used
A9: Hidden dimension | C9: =INDEX('Model Presets'!$B$5:$B$13,MATCH($B$6,'Model Presets'!$A$5:$A$13,0)) | E9: =IF(D9="",C9,D9) | G9: Leave the override column empty unless you know your model's real shape.
A10: Layers | C10: =INDEX('Model Presets'!$C$5:$C$13,MATCH($B$6,'Model Presets'!$A$5:$A$13,0)) | E10: =IF(D10="",C10,D10)
A11: Attention heads | C11: =INDEX('Model Presets'!$D$5:$D$13,MATCH($B$6,'Model Presets'!$A$5:$A$13,0)) | E11: =IF(D11="",C11,D11)
A12: Feed-forward multiplier | C12: =INDEX('Model Presets'!$E$5:$E$13,MATCH($B$6,'Model Presets'!$A$5:$A$13,0)) | E12: =IF(D12="",C12,D12)
A13: Output vocabulary / output width | C13: =INDEX('Model Presets'!$F$5:$F$13,MATCH($B$6,'Model Presets'!$A$5:$A$13,0)) | E13: =IF(D13="",C13,D13) | G13: For a tabular model this is your output width, not a text vocabulary.
A14: Parameter count | C14: =(4+2*E12)*E9^2*E10+2*E13*E9 | E14: =IF(D14="",C14,D14) | G14: Calculated from the architecture above. Override only if you know your exact count.
A15: WARNING: if you override the parameter count with a value that does not match the architecture above, the weights, gradients and optimizer lines will use your number but the activation line will still use the architecture. Change the architecture instead when you can.
A17: STEP 2 — YOUR TRAINING CONFIGURATION
A18: Batch size (rows per batch) | B18: 256 | C18: Examples processed at once. Drives activations linearly.
A19: Sequence length (tokens per example) | B19: 100 | C19: Tokens, or features, per example. Drives activations linearly.
A20: Compute precision | B20: BF16 mixed precision | C20: BF16 mixed precision keeps weights in FP32 storage and computes in BF16.
A21: Optimizer | B21: Standard Adam | C21: 8-bit Adam cuts optimizer state from 8 to 2 bytes per parameter.
A22: Activation checkpointing | B22: No | C22: The highest-leverage lever. Costs roughly a third more training time.
A23: Memory-efficient attention | B23: Yes | C23: Answer No only if your attention stores the full probability matrix. See the caution below.
A24: CAUTION on memory-efficient attention: answering No adds layers x batch size x attention heads x sequence length squared x activation bytes. That term grows with the SQUARE of sequence length and can dominate everything else. It is calculated, not validated — the benchmark behind this workbook only ever ran memory-efficient attention.
A26: STEP 3 — YOUR HARDWARE
A27: GPU | B27: NVIDIA H100 80GB | C27: One GPU. Multi-GPU strategies are a later article in the series.
A28: Usable capacity from the table (GB) | B28: =INDEX('GPU Capacity'!$C$5:$C$16,MATCH($B$27,'GPU Capacity'!$A$5:$A$16,0))
A29: Your capacity override (GB) | C29: Fill this in if your card is not in the list, or you want to reserve capacity for something else.
A30: Capacity used in the verdict (GB) | B30: =IF(B29="",B28,B29)
A32: OVERHEAD ALLOWANCES — edit only if you have better measurements
A33: CUDA context (GB) | B33: 0.6 | C33: Estimated. Driver and kernel-library state. Invisible to PyTorch's memory API, so it cannot be measured from inside training. Source: benchmark/predictions.py, CUDA_CONTEXT_OVERHEAD_GB.
A34: Fragmentation allowance, no activation checkpointing (GB) | B34: 1.2 | C34: Measured range 0.95-1.11 GB across two configurations in benchmark/reference-run/results.csv. Source: benchmark/predictions.py, FRAGMENTATION_GB.
A35: Fragmentation allowance, with activation checkpointing (GB) | B35: 5.2 | C35: Measured range 3.58-6.12 GB across three configurations in benchmark/reference-run/results.csv. Provisional. Source: benchmark/predictions.py, CHECKPOINTING_FRAGMENTATION_GB.
A37: RESULT — THE LINE ITEMS (GB)
A38: Line item | B38: Memory (GB)
A39: Weights | B39: =E14*4/1000000000 | C39: Parameter count x 4 bytes. Storage is FP32 even under BF16 mixed precision.
A40: Gradients | B40: =E14*4/1000000000 | C40: One gradient per weight, same precision as the weight.
A41: Optimizer states | B41: =E14*$B$63/1000000000 | C41: Standard Adam: 8 bytes per parameter. 8-bit Adam: 2 bytes per parameter.
A42: BF16 weight cache | B42: =IF($B$20="BF16 mixed precision",E14*2,0)/1000000000 | C42: Exists only under BF16 mixed precision. Released before the peak in most runs.
A43: Activations | B43: =IF($B$22="Yes",$B$70,$B$69)/1000000000 | C43: The dynamic line item. Scales with batch size x sequence length.
A44: implied bytes per element per layer | B44: =$B$67/$B$64 | C44: Ties back to the article's ~40 bytes. Exact at feed-forward multiplier 4 with BF16 compute; higher in FP32. Ignores activation checkpointing.
A46: PEAK MEMORY
A47: Phase peak 1 — backward pass, recomputing (GB) | B47: =B39+B41+$B$70/1000000000 | C47: With activation checkpointing on, peak memory is the LARGEST of these three moments, not their sum.
...

Sheet Model Presets
A1: Architecture presets — pick a model size on the Sizing Tool tab and these fill in automatically
A2: You never have to know these numbers. They exist so the activation math has an architecture to work with. Override any of them on the Sizing Tool tab if you know your real model's shape.
A4: Preset | B4: Hidden dimension | C4: Layers | D4: Attention heads | E4: Feed-forward multiplier | F4: Output vocabulary / output width | G4: Parameter count (calculated) | H4: Source of these shapes
A5: Article 1 worked model (1.0B) | B5: 2048 | C5: 20 | D5: 16 | E5: 4 | F5: 1000 | G5: =(4+2*E5)*B5^2*C5+2*F5*B5 | H5: Exact architecture benchmarked in benchmark/reference-run/results.csv
A6: 125M | B6: 768 | C6: 12 | D6: 12 | E6: 4 | F6: 32000 | G6: =(4+2*E6)*B6^2*C6+2*F6*B6 | H6: Conventional transformer shape for this size class
A7: 350M | B7: 1024 | C7: 24 | D7: 16 | E7: 4 | F7: 32000 | G7: =(4+2*E7)*B7^2*C7+2*F7*B7 | H7: Conventional transformer shape for this size class
A8: 1B | B8: 2048 | C8: 18 | D8: 16 | E8: 4 | F8: 32000 | G8: =(4+2*E8)*B8^2*C8+2*F8*B8 | H8: Conventional transformer shape for this size class
A9: 3B | B9: 2560 | C9: 32 | D9: 20 | E9: 4 | F9: 32000 | G9: =(4+2*E9)*B9^2*C9+2*F9*B9 | H9: Conventional transformer shape for this size class
A10: 7B | B10: 4096 | C10: 32 | D10: 32 | E10: 4 | F10: 32000 | G10: =(4+2*E10)*B10^2*C10+2*F10*B10 | H10: Conventional transformer shape for this size class
A11: 13B | B11: 5120 | C11: 40 | D11: 40 | E11: 4 | F11: 32000 | G11: =(4+2*E11)*B11^2*C11+2*F11*B11 | H11: Conventional transformer shape for this size class
A12: 30B | B12: 6656 | C12: 60 | D12: 52 | E12: 4 | F12: 32000 | G12: =(4+2*E12)*B12^2*C12+2*F12*B12 | H12: Conventional transformer shape for this size class
A13: 70B | B13: 8192 | C13: 80 | D13: 64 | E13: 4 | F13: 32000 | G13: =(4+2*E13)*B13^2*C13+2*F13*B13 | H13: Conventional transformer shape for this size class
A15: Parameter-count formula: (4 + 2 x feed-forward multiplier) x hidden dimension^2 x layers + 2 x output vocabulary x hidden dimension. Source: benchmark/model.py, analytical_param_count(), in odog96/gpu-sizing-playbook. It ignores biases and layer-norm parameters (~0.05% of the total: the Article 1 worked model measures 1,011,262,440 parameters on device vs. 1,010,728,960 calculated here).

Sheet GPU Capacity
A1: GPU usable capacity
A2: Units are decimal GB (1 GB = 1,000,000,000 bytes) throughout this workbook, matching benchmark/predictions.py. A card's advertised size is in GiB, which is why an '80 GB' card shows 85 GB here.
A4: GPU | B4: Advertised size (GiB) | C4: Usable capacity (GB, decimal) | D4: Basis
A5: NVIDIA H100 80GB | B5: 80 | C5: =79.18*1024^3/1000000000 | D5: Measured — torch reported 79.18 GiB usable in this benchmark's own out-of-memory messages
A6: NVIDIA A100 80GB | B6: 80 | C6: =79.18*1024^3/1000000000 | D6: Estimated — same 80 GiB class as the measured H100 row above
A7: NVIDIA A100 40GB | B7: 40 | C7: =B7*1024^3/1000000000*0.99 | D7: Estimated — advertised size less 1% for driver reserve
A8: NVIDIA L40S 48GB | B8: 48 | C8: =B8*1024^3/1000000000*0.99 | D8: Estimated — advertised size less 1% for driver reserve
A9: NVIDIA RTX PRO 6000 Blackwell 96GB | B9: 96 | C9: =B9*1024^3/1000000000*0.99 | D9: Estimated — advertised size less 1% for driver reserve
A10: NVIDIA A10G 24GB | B10: 24 | C10: =B10*1024^3/1000000000*0.99 | D10: Estimated — advertised size less 1% for driver reserve
A11: NVIDIA RTX 4090 24GB | B11: 24 | C11: =B11*1024^3/1000000000*0.99 | D11: Estimated — advertised size less 1% for driver reserve
A12: NVIDIA H200 141GB | B12: 141 | C12: =B12*1024^3/1000000000*0.99 | D12: Estimated — advertised size less 1% for driver reserve
A13: NVIDIA B200 180GB | B13: 180 | C13: =B13*1024^3/1000000000*0.99 | D13: Estimated — advertised size less 1% for driver reserve
A14: NVIDIA H100 NVL 94GB | B14: 94 | C14: =B14*1024^3/1000000000*0.99 | D14: Estimated — advertised size less 1% for driver reserve
A15: NVIDIA RTX 6000 Ada 48GB | B15: 48 | C15: =B15*1024^3/1000000000*0.99 | D15: Estimated — advertised size less 1% for driver reserve
A16: Other — use the override cell on the Sizing Tool tab | B16: 0 | C16: =0 | D16: Enter your own usable capacity on the Sizing Tool tab

Sheet Validation
A1: Validation — the same formulas, run against all 24 configurations of the H100 80GB sweep
A2: Every white column is calculated live by the same arithmetic as the Sizing Tool tab. The measured columns come from benchmark/reference-run/results.csv in odog96/gpu-sizing-playbook. Error is calculated peak allocated against measured peak allocated; blank where the configuration ran out of memory.
B3: Usable capacity used for the out-of-memory call (GB): | C3: =79.18*1024^3/1000000000
A5: Lever | B5: Lever value | C5: Hidden dim | D5: Layers | E5: Heads | F5: FF mult | G5: Vocab | H5: Batch size | I5: Sequence length | J5: Precision | K5: Optimizer | L5: Checkpointing | M5: Parameter count | N5: Activation bytes/elem | O5: Elements B*S*d | P5: Elements B*S*f*d | Q5: Per-layer bytes | R5: Once-per-model bytes | S5: Activations no ckpt (bytes) | T5: Activations ckpt (bytes) | U5: Segment transient (bytes) | V5: Weights (GB) | W5: Gradients (GB) | X5: Optimizer (GB) | Y5: BF16 cache (GB) | Z5: Activations (GB) | AA5: Phase 1 backward (GB) | AB5: Phase 2 opt step (GB) | AC5: Phase 3 forward (GB) | AD5: PEAK ALLOCATED calc (GB) | AE5: RESERVED calc (GB) | AF5: Predicted | AG5: Measured allocated (GB) | AH5: Measured reserved (GB) | AI5: Error vs measured
A6: baseline | B6: baseline | C6: 2048 | D6: 20 | E6: 16 | F6: 4 | G6: 1000 | H6: 256 | I6: 100 | J6: amp_bf16 | K6: adam | L6: No | M6: 1011262440 | N6: =IF(J6="amp_bf16",2,4) | O6: =H6*I6*C6 | P6: =H6*I6*F6*C6 | Q6: =9*O6*N6+2*P6*N6+2*O6+P6 | R6: =O6*N6+H6*I6*G6*N6+IF(J6="amp_bf16",H6*I6*G6*4,0) | S6: =Q6*D6+R6 | T6: =(D6+3)*O6*4+7*O6*N6+3*P6*N6+O6+H6*I6*G6*N6 | U6: =(2*F6*C6+3*C6)*H6*I6*N6 | V6: =M6*4/1000000000 | W6: =M6*4/1000000000 | X6: =M6*IF(K6="adam8bit",2,8)/1000000000 | Y6: =IF(J6="amp_bf16",M6*2,0)/1000000000 | Z6: =IF(L6="Yes",T6,S6)/1000000000 | AA6: =V6+X6+T6/1000000000 | AB6: =V6+W6+X6+IF(K6="adam",W6,0) | AC6: =V6+X6+Y6+D6*O6*4/1000000000+U6/1000000000+(H6*I6*G6*N6+IF(J6="amp_bf16",H6*I6*G6*4,0))/1000000000 | AD6: =IF(L6="Yes",MAX(AA6,AB6,AC6),V6+W6+X6+Y6+Z6) | AE6: =AD6+0.6+IF(L6="Yes",5.2,1.2) | AF6: =IF(AE6>$C$3,"OOM","fits") | AG6: 59.2206 | AH6: 60.1673 | AI6: =IF(ISNUMBER(AG6),(AD6-AG6)/AG6,"")
A7: batch_size | B7: 256 | C7: 2048 | D7: 20 | E7: 16 | F7: 4 | G7: 1000 | H7: 256 | I7: 100 | J7: amp_bf16 | K7: adam | L7: No | M7: 1011262440 | N7: =IF(J7="amp_bf16",2,4) | O7: =H7*I7*C7 | P7: =H7*I7*F7*C7 | Q7: =9*O7*N7+2*P7*N7+2*O7+P7 | R7: =O7*N7+H7*I7*G7*N7+IF(J7="amp_bf16",H7*I7*G7*4,0) | S7: =Q7*D7+R7 | T7: =(D7+3)*O7*4+7*O7*N7+3*P7*N7+O7+H7*I7*G7*N7 | U7: =(2*F7*C7+3*C7)*H7*I7*N7 | V7: =M7*4/1000000000 | W7: =M7*4/1000000000 | X7: =M7*IF(K7="adam8bit",2,8)/1000000000 | Y7: =IF(J7="amp_bf16",M7*2,0)/1000000000 | Z7: =IF(L7="Yes",T7,S7)/1000000000 | AA7: =V7+X7+T7/1000000000 | AB7: =V7+W7+X7+IF(K7="adam",W7,0) | AC7: =V7+X7+Y7+D7*O7*4/1000000000+U7/1000000000+(H7*I7*G7*N7+IF(J7="amp_bf16",H7*I7*G7*4,0))/1000000000 | AD7: =IF(L7="Yes",MAX(AA7,AB7,AC7),V7+W7+X7+Y7+Z7) | AE7: =AD7+0.6+IF(L7="Yes",5.2,1.2) | AF7: =IF(AE7>$C$3,"OOM","fits") | AG7: 59.2206 | AH7: 60.1673 | AI7: =IF(ISNUMBER(AG7),(AD7-AG7)/AG7,"")
A8: batch_size | B8: 1024 | C8: 2048 | D8: 20 | E8: 16 | F8: 4 | G8: 1000 | H8: 1024 | I8: 100 | J8: amp_bf16 | K8: adam | L8: No | M8: 1010728960 | N8: =IF(J8="amp_bf16",2,4) | O8: =H8*I8*C8 | P8: =H8*I8*F8*C8 | Q8: =9*O8*N8+2*P8*N8+2*O8+P8 | R8: =O8*N8+H8*I8*G8*N8+IF(J8="amp_bf16",H8*I8*G8*4,0) | S8: =Q8*D8+R8 | T8: =(D8+3)*O8*4+7*O8*N8+3*P8*N8+O8+H8*I8*G8*N8 | U8: =(2*F8*C8+3*C8)*H8*I8*N8 | V8: =M8*4/1000000000 | W8: =M8*4/1000000000 | X8: =M8*IF(K8="adam8bit",2,8)/1000000000 | Y8: =IF(J8="amp_bf16",M8*2,0)/1000000000 | Z8: =IF(L8="Yes",T8,S8)/1000000000 | AA8: =V8+X8+T8/1000000000 | AB8: =V8+W8+X8+IF(K8="adam",W8,0) | AC8: =V8+X8+Y8+D8*O8*4/1000000000+U8/1000000000+(H8*I8*G8*N8+IF(J8="amp_bf16",H8*I8*G8*4,0))/1000000000 | AD8: =IF(L8="Yes",MAX(AA8,AB8,AC8),V8+W8+X8+Y8+Z8) | AE8: =AD8+0.6+IF(L8="Yes",5.2,1.2) | AF8: =IF(AE8>$C$3,"OOM","fits") | AG8: OOM | AH8: OOM | AI8: =IF(ISNUMBER(AG8),(AD8-AG8)/AG8,"")
A9: batch_size | B9: 4096 | C9: 2048 | D9: 20 | E9: 16 | F9: 4 | G9: 1000 | H9: 4096 | I9: 100 | J9: amp_bf16 | K9: adam | L9: No | M9: 1010728960 | N9: =IF(J9="amp_bf16",2,4) | O9: =H9*I9*C9 | P9: =H9*I9*F9*C9 | Q9: =9*O9*N9+2*P9*N9+2*O9+P9 | R9: =O9*N9+H9*I9*G9*N9+IF(J9="amp_bf16",H9*I9*G9*4,0) | S9: =Q9*D9+R9 | T9: =(D9+3)*O9*4+7*O9*N9+3*P9*N9+O9+H9*I9*G9*N9 | U9: =(2*F9*C9+3*C9)*H9*I9*N9 | V9: =M9*4/1000000000 | W9: =M9*4/1000000000 | X9: =M9*IF(K9="adam8bit",2,8)/1000000000 | Y9: =IF(J9="amp_bf16",M9*2,0)/1000000000 | Z9: =IF(L9="Yes",T9,S9)/1000000000 | AA9: =V9+X9+T9/1000000000 | AB9: =V9+W9+X9+IF(K9="adam",W9,0) | AC9: =V9+X9+Y9+D9*O9*4/1000000000+U9/1000000000+(H9*I9*G9*N9+IF(J9="amp_bf16",H9*I9*G9*4,0))/1000000000 | AD9: =IF(L9="Yes",MAX(AA9,AB9,AC9),V9+W9+X9+Y9+Z9) | AE9: =AD9+0.6+IF(L9="Yes",5.2,1.2) | AF9: =IF(AE9>$C$3,"OOM","fits") | AG9: OOM | AH9: OOM | AI9: =IF(ISNUMBER(AG9),(AD9-AG9)/AG9,"")
A10: seq_len | B10: 100 | C10: 2048 | D10: 20 | E10: 16 | F10: 4 | G10: 1000 | H10: 256 | I10: 100 | J10: amp_bf16 | K10: adam | L10: No | M10: 1011262440 | N10: =IF(J10="amp_bf16",2,4) | O10: =H10*I10*C10 | P10: =H10*I10*F10*C10 | Q10: =9*O10*N10+2*P10*N10+2*O10+P10 | R10: =O10*N10+H10*I10*G10*N10+IF(J10="amp_bf16",H10*I10*G10*4,0) | S10: =Q10*D10+R10 | T10: =(D10+3)*O10*4+7*O10*N10+3*P10*N10+O10+H10*I10*G10*N10 | U10: =(2*F10*C10+3*C10)*H10*I10*N10 | V10: =M10*4/1000000000 | W10: =M10*4/1000000000 | X10: =M10*IF(K10="adam8bit",2,8)/1000000000 | Y10: =IF(J10="amp_bf16",M10*2,0)/1000000000 | Z10: =IF(L10="Yes",T10,S10)/1000000000 | AA10: =V10+X10+T10/1000000000 | AB10: =V10+W10+X10+IF(K10="adam",W10,0) | AC10: =V10+X10+Y10+D10*O10*4/1000000000+U10/1000000000+(H10*I10*G10*N10+IF(J10="amp_bf16",H10*I10*G10*4,0))/1000000000 | AD10: =IF(L10="Yes",MAX(AA10,AB10,AC10),V10+W10+X10+Y10+Z10) | AE10: =AD10+0.6+IF(L10="Yes",5.2,1.2) | AF10: =IF(AE10>$C$3,"OOM","fits") | AG10: 59.2206 | AH10: 60.1673 | AI10: =IF(ISNUMBER(AG10),(AD10-AG10)/AG10,"")
A11: seq_len | B11: 512 | C11: 2048 | D11: 20 | E11: 16 | F11: 4 | G11: 1000 | H11: 256 | I11: 512 | J11: amp_bf16 | K11: adam | L11: No | M11: 1010728960 | N11: =IF(J11="amp_bf16",2,4) | O11: =H11*I11*C11 | P11: =H11*I11*F11*C11 | Q11: =9*O11*N11+2*P11*N11+2*O11+P11 | R11: =O11*N11+H11*I11*G11*N11+IF(J11="amp_bf16",H11*I11*G11*4,0) | S11: =Q11*D11+R11 | T11: =(D11+3)*O11*4+7*O11*N11+3*P11*N11+O11+H11*I11*G11*N11 | U11: =(2*F11*C11+3*C11)*H11*I11*N11 | V11: =M11*4/1000000000 | W11: =M11*4/1000000000 | X11: =M11*IF(K11="adam8bit",2,8)/1000000000 | Y11: =IF(J11="amp_bf16",M11*2,0)/1000000000 | Z11: =IF(L11="Yes",T11,S11)/1000000000 | AA11: =V11+X11+T11/1000000000 | AB11: =V11+W11+X11+IF(K11="adam",W11,0) | AC11: =V11+X11+Y11+D11*O11*4/1000000000+U11/1000000000+(H11*I11*G11*N11+IF(J11="amp_bf16",H11*I11*G11*4,0))/1000000000 | AD11: =IF(L11="Yes",MAX(AA11,AB11,AC11),V11+W11+X11+Y11+Z11) | AE11: =AD11+0.6+IF(L11="Yes",5.2,1.2) | AF11: =IF(AE11>$C$3,"OOM","fits") | AG11: OOM | AH11: OOM | AI11: =IF(ISNUMBER(AG11),(AD11-AG11)/AG11,"")
A12: seq_len | B12: 1024 | C12: 2048 | D12: 20 | E12: 16 | F12: 4 | G12: 1000 | H12: 256 | I12: 1024 | J12: amp_bf16 | K12: adam | L12: No | M12: 1010728960 | N12: =IF(J12="amp_bf16",2,4) | O12: =H12*I12*C12 | P12: =H12*I12*F12*C12 | Q12: =9*O12*N12+2*P12*N12+2*O12+P12 | R12: =O12*N12+H12*I12*G12*N12+IF(J12="amp_bf16",H12*I12*G12*4,0) | S12: =Q12*D12+R12 | T12: =(D12+3)*O12*4+7*O12*N12+3*P12*N12+O12+H12*I12*G12*N12 | U12: =(2*F12*C12+3*C12)*H12*I12*N12 | V12: =M12*4/1000000000 | W12: =M12*4/1000000000 | X12: =M12*IF(K12="adam8bit",2,8)/1000000000 | Y12: =IF(J12="amp_bf16",M12*2,0)/1000000000 | Z12: =IF(L12="Yes",T12,S12)/1000000000 | AA12: =V12+X12+T12/1000000000 | AB12: =V12+W12+X12+IF(K12="adam",W12,0) | AC12: =V12+X12+Y12+D12*O12*4/1000000000+U12/1000000000+(H12*I12*G12*N12+IF(J12="amp_bf16",H12*I12*G12*4,0))/1000000000 | AD12: =IF(L12="Yes",MAX(AA12,AB12,AC12),V12+W12+X12+Y12+Z12) | AE12: =AD12+0.6+IF(L12="Yes",5.2,1.2) | AF12: =IF(AE12>$C$3,"OOM","fits") | AG12: OOM | AH12: OOM | AI12: =IF(ISNUMBER(AG12),(AD12-AG12)/AG12,"")
A13: seq_len | B13: 2048 | C13: 2048 | D13: 20 | E13: 16 | F13: 4 | G13: 1000 | H13: 256 | I13: 2048 | J13: amp_bf16 | K13: adam | L13: No | M13: 1010728960 | N13: =IF(J13="amp_bf16",2,4) | O13: =H13*I13*C13 | P13: =H13*I13*F13*C13 | Q13: =9*O13*N13+2*P13*N13+2*O13+P13 | R13: =O13*N13+H13*I13*G13*N13+IF(J13="amp_bf16",H13*I13*G13*4,0) | S13: =Q13*D13+R13 | T13: =(D13+3)*O13*4+7*O13*N13+3*P13*N13+O13+H13*I13*G13*N13 | U13: =(2*F13*C13+3*C13)*H13*I13*N13 | V13: =M13*4/1000000000 | W13: =M13*4/1000000000 | X13: =M13*IF(K13="adam8bit",2,8)/1000000000 | Y13: =IF(J13="amp_bf16",M13*2,0)/1000000000 | Z13: =IF(L13="Yes",T13,S13)/1000000000 | AA13: =V13+X13+T13/1000000000 | AB13: =V13+W13+X13+IF(K13="adam",W13,0) | AC13: =V13+X13+Y13+D13*O13*4/1000000000+U13/1000000000+(H13*I13*G13*N13+IF(J13="amp_bf16",H13*I13*G13*4,0))/1000000000 | AD13: =IF(L13="Yes",MAX(AA13,AB13,AC13),V13+W13+X13+Y13+Z13) | AE13: =AD13+0.6+IF(L13="Yes",5.2,1.2) | AF13: =IF(AE13>$C$3,"OOM","fits") | AG13: OOM | AH13: OOM | AI13: =IF(ISNUMBER(AG13),(AD13-AG13)/AG13,"")
A14: optimizer | B14: adam | C14: 2048 | D14: 20 | E14: 16 | F14: 4 | G14: 1000 | H14: 256 | I14: 100 | J14: amp_bf16 | K14: adam | L14: No | M14: 1011262440 | N14: =IF(J14="amp_bf16",2,4) | O14: =H14*I14*C14 | P14: =H14*I14*F14*C14 | Q14: =9*O14*N14+2*P14*N14+2*O14+P14 | R14: =O14*N14+H14*I14*G14*N14+IF(J14="amp_bf16",H14*I14*G14*4,0) | S14: =Q14*D14+R14 | T14: =(D14+3)*O14*4+7*O14*N14+3*P14*N14+O14+H14*I14*G14*N14 | U14: =(2*F14*C14+3*C14)*H14*I14*N14 | V14: =M14*4/1000000000 | W14: =M14*4/1000000000 | X14: =M14*IF(K14="adam8bit",2,8)/1000000000 | Y14: =IF(J14="amp_bf16",M14*2,0)/1000000000 | Z14: =IF(L14="Yes",T14,S14)/1000000000 | AA14: =V14+X14+T14/1000000000 | AB14: =V14+W14+X14+IF(K14="adam",W14,0) | AC14: =V14+X14+Y14+D14*O14*4/1000000000+U14/1000000000+(H14*I14*G14*N14+IF(J14="amp_bf16",H14*I14*G14*4,0))/1000000000 | AD14: =IF(L14="Yes",MAX(AA14,AB14,AC14),V14+W14+X14+Y14+Z14) | AE14: =AD14+0.6+IF(L14="Yes",5.2,1.2) | AF14: =IF(AE14>$C$3,"OOM","fits") | AG14: 59.2206 | AH14: 60.1673 | AI14: =IF(ISNUMBER(AG14),(AD14-AG14)/AG14,"")
A15: optimizer | B15: adam8bit | C15: 2048 | D15: 20 | E15: 16 | F15: 4 | G15: 1000 | H15: 256 | I15: 100 | J15: amp_bf16 | K15: adam8bit | L15: No | M15: 1011262440 | N15: =IF(J15="amp_bf16",2,4) | O15: =H15*I15*C15 | P15: =H15*I15*F15*C15 | Q15: =9*O15*N15+2*P15*N15+2*O15+P15 | R15: =O15*N15+H15*I15*G15*N15+IF(J15="amp_bf16",H15*I15*G15*4,0) | S15: =Q15*D15+R15 | T15: =(D15+3)*O15*4+7*O15*N15+3*P15*N15+O15+H15*I15*G15*N15 | U15: =(2*F15*C15+3*C15)*H15*I15*N15 | V15: =M15*4/1000000000 | W15: =M15*4/1000000000 | X15: =M15*IF(K15="adam8bit",2,8)/1000000000 | Y15: =IF(J15="amp_bf16",M15*2,0)/1000000000 | Z15: =IF(L15="Yes",T15,S15)/1000000000 | AA15: =V15+X15+T15/1000000000 | AB15: =V15+W15+X15+IF(K15="adam",W15,0) | AC15: =V15+X15+Y15+D15*O15*4/1000000000+U15/1000000000+(H15*I15*G15*N15+IF(J15="amp_bf16",H15*I15*G15*4,0))/1000000000 | AD15: =IF(L15="Yes",MAX(AA15,AB15,AC15),V15+W15+X15+Y15+Z15) | AE15: =AD15+0.6+IF(L15="Yes",5.2,1.2) | AF15: =IF(AE15>$C$3,"OOM","fits") | AG15: 53.1814 | AH15: 54.2932 | AI15: =IF(ISNUMBER(AG15),(AD15-AG15)/AG15,"")
A16: checkpointing | B16: False | C16: 2048 | D16: 20 | E16: 16 | F16: 4 | G16: 1000 | H16: 256 | I16: 100 | J16: amp_bf16 | K16: adam | L16: No | M16: 1011262440 | N16: =IF(J16="amp_bf16",2,4) | O16: =H16*I16*C16 | P16: =H16*I16*F16*C16 | Q16: =9*O16*N16+2*P16*N16+2*O16+P16 | R16: =O16*N16+H16*I16*G16*N16+IF(J16="amp_bf16",H16*I16*G16*4,0) | S16: =Q16*D16+R16 | T16: =(D16+3)*O16*4+7*O16*N16+3*P16*N16+O16+H16*I16*G16*N16 | U16: =(2*F16*C16+3*C16)*H16*I16*N16 | V16: =M16*4/1000000000 | W16: =M16*4/1000000000 | X16: =M16*IF(K16="adam8bit",2,8)/1000000000 | Y16: =IF(J16="amp_bf16",M16*2,0)/1000000000 | Z16: =IF(L16="Yes",T16,S16)/1000000000 | AA16: =V16+X16+T16/1000000000 | AB16: =V16+W16+X16+IF(K16="adam",W16,0) | AC16: =V16+X16+Y16+D16*O16*4/1000000000+U16/1000000000+(H16*I16*G16*N16+IF(J16="amp_bf16",H16*I16*G16*4,0))/1000000000 | AD16: =IF(L16="Yes",MAX(AA16,AB16,AC16),V16+W16+X16+Y16+Z16) | AE16: =AD16+0.6+IF(L16="Yes",5.2,1.2) | AF16: =IF(AE16>$C$3,"OOM","fits") | AG16: 59.2206 | AH16: 60.1673 | AI16: =IF(ISNUMBER(AG16),(AD16-AG16)/AG16,"")
A17: checkpointing | B17: True | C17: 2048 | D17: 20 | E17: 16 | F17: 4 | G17: 1000 | H17: 256 | I17: 100 | J17: amp_bf16 | K17: adam | L17: Yes | M17: 1011262440 | N17: =IF(J17="amp_bf16",2,4) | O17: =H17*I17*C17 | P17: =H17*I17*F17*C17 | Q17: =9*O17*N17+2*P17*N17+2*O17+P17 | R17: =O17*N17+H17*I17*G17*N17+IF(J17="amp_bf16",H17*I17*G17*4,0) | S17: =Q17*D17+R17 | T17: =(D17+3)*O17*4+7*O17*N17+3*P17*N17+O17+H17*I17*G17*N17 | U17: =(2*F17*C17+3*C17)*H17*I17*N17 | V17: =M17*4/1000000000 | W17: =M17*4/1000000000 | X17: =M17*IF(K17="adam8bit",2,8)/1000000000 | Y17: =IF(J17="amp_bf16",M17*2,0)/1000000000 | Z17: =IF(L17="Yes",T17,S17)/1000000000 | AA17: =V17+X17+T17/1000000000 | AB17: =V17+W17+X17+IF(K17="adam",W17,0) | AC17: =V17+X17+Y17+D17*O17*4/1000000000+U17/1000000000+(H17*I17*G17*N17+IF(J17="amp_bf16",H17*I17*G17*4,0))/1000000000 | AD17: =IF(L17="Yes",MAX(AA17,AB17,AC17),V17+W17+X17+Y17+Z17) | AE17: =AD17+0.6+IF(L17="Yes",5.2,1.2) | AF17: =IF(AE17>$C$3,"OOM","fits") | AG17: 20.3462 | AH17: 26.4619 | AI17: =IF(ISNUMBER(AG17),(AD17-AG17)/AG17,"")
A18: checkpointing_batch | B18: 256 | C18: 2048 | D18: 20 | E18: 16 | F18: 4 | G18: 1000 | H18: 256 | I18: 100 | J18: amp_bf16 | K18: adam | L18: Yes | M18: 1011262440 | N18: =IF(J18="amp_bf16",2,4) | O18: =H18*I18*C18 | P18: =H18*I18*F18*C18 | Q18: =9*O18*N18+2*P18*N18+2*O18+P18 | R18: =O18*N18+H18*I18*G18*N18+IF(J18="amp_bf16",H18*I18*G18*4,0) | S18: =Q18*D18+R18 | T18: =(D18+3)*O18*4+7*O18*N18+3*P18*N18+O18+H18*I18*G18*N18 | U18: =(2*F18*C18+3*C18)*H18*I18*N18 | V18: =M18*4/1000000000 | W18: =M18*4/1000000000 | X18: =M18*IF(K18="adam8bit",2,8)/1000000000 | Y18: =IF(J18="amp_bf16",M18*2,0)/1000000000 | Z18: =IF(L18="Yes",T18,S18)/1000000000 | AA18: =V18+X18+T18/1000000000 | AB18: =V18+W18+X18+IF(K18="adam",W18,0) | AC18: =V18+X18+Y18+D18*O18*4/1000000000+U18/1000000000+(H18*I18*G18*N18+IF(J18="amp_bf16",H18*I18*G18*4,0))/1000000000 | AD18: =IF(L18="Yes",MAX(AA18,AB18,AC18),V18+W18+X18+Y18+Z18) | AE18: =AD18+0.6+IF(L18="Yes",5.2,1.2) | AF18: =IF(AE18>$C$3,"OOM","fits") | AG18: 20.3462 | AH18: 26.4619 | AI18: =IF(ISNUMBER(AG18),(AD18-AG18)/AG18,"")
A19: checkpointing_batch | B19: 1024 | C19: 2048 | D19: 20 | E19: 16 | F19: 4 | G19: 1000 | H19: 1024 | I19: 100 | J19: amp_bf16 | K19: adam | L19: Yes | M19: 1011262440 | N19: =IF(J19="amp_bf16",2,4) | O19: =H19*I19*C19 | P19: =H19*I19*F19*C19 | Q19: =9*O19*N19+2*P19*N19+2*O19+P19 | R19: =O19*N19+H19*I19*G19*N19+IF(J19="amp_bf16",H19*I19*G19*4,0) | S19: =Q19*D19+R19 | T19: =(D19+3)*O19*4+7*O19*N19+3*P19*N19+O19+H19*I19*G19*N19 | U19: =(2*F19*C19+3*C19)*H19*I19*N19 | V19: =M19*4/1000000000 | W19: =M19*4/1000000000 | X19: =M19*IF(K19="adam8bit",2,8)/1000000000 | Y19: =IF(J19="amp_bf16",M19*2,0)/1000000000 | Z19: =IF(L19="Yes",T19,S19)/1000000000 | AA19: =V19+X19+T19/1000000000 | AB19: =V19+W19+X19+IF(K19="adam",W19,0) | AC19: =V19+X19+Y19+D19*O19*4/1000000000+U19/1000000000+(H19*I19*G19*N19+IF(J19="amp_bf16",H19*I19*G19*4,0))/1000000000 | AD19: =IF(L19="Yes",MAX(AA19,AB19,AC19),V19+W19+X19+Y19+Z19) | AE19: =AD19+0.6+IF(L19="Yes",5.2,1.2) | AF19: =IF(AE19>$C$3,"OOM","fits") | AG19: 40.0338 | AH19: 44.3883 | AI19: =IF(ISNUMBER(AG19),(AD19-AG19)/AG19,"")
A20: checkpointing_batch | B20: 4096 | C20: 2048 | D20: 20 | E20: 16 | F20: 4 | G20: 1000 | H20: 4096 | I20: 100 | J20: amp_bf16 | K20: adam | L20: Yes | M20: 1010728960 | N20: =IF(J20="amp_bf16",2,4) | O20: =H20*I20*C20 | P20: =H20*I20*F20*C20 | Q20: =9*O20*N20+2*P20*N20+2*O20+P20 | R20: =O20*N20+H20*I20*G20*N20+IF(J20="amp_bf16",H20*I20*G20*4,0) | S20: =Q20*D20+R20 | T20: =(D20+3)*O20*4+7*O20*N20+3*P20*N20+O20+H20*I20*G20*N20 | U20: =(2*F20*C20+3*C20)*H20*I20*N20 | V20: =M20*4/1000000000 | W20: =M20*4/1000000000 | X20: =M20*IF(K20="adam8bit",2,8)/1000000000 | Y20: =IF(J20="amp_bf16",M20*2,0)/1000000000 | Z20: =IF(L20="Yes",T20,S20)/1000000000 | AA20: =V20+X20+T20/1000000000 | AB20: =V20+W20+X20+IF(K20="adam",W20,0) | AC20: =V20+X20+Y20+D20*O20*4/1000000000+U20/1000000000+(H20*I20*G20*N20+IF(J20="amp_bf16",H20*I20*G20*4,0))/1000000000 | AD20: =IF(L20="Yes",MAX(AA20,AB20,AC20),V20+W20+X20+Y20+Z20) | AE20: =AD20+0.6+IF(L20="Yes",5.2,1.2) | AF20: =IF(AE20>$C$3,"OOM","fits") | AG20: OOM | AH20: OOM | AI20: =IF(ISNUMBER(AG20),(AD20-AG20)/AG20,"")
A21: checkpointing_seq | B21: 100 | C21: 2048 | D21: 20 | E21: 16 | F21: 4 | G21: 1000 | H21: 256 | I21: 100 | J21: amp_bf16 | K21: adam | L21: Yes | M21: 1011262440 | N21: =IF(J21="amp_bf16",2,4) | O21: =H21*I21*C21 | P21: =H21*I21*F21*C21 | Q21: =9*O21*N21+2*P21*N21+2*O21+P21 | R21: =O21*N21+H21*I21*G21*N21+IF(J21="amp_bf16",H21*I21*G21*4,0) | S21: =Q21*D21+R21 | T21: =(D21+3)*O21*4+7*O21*N21+3*P21*N21+O21+H21*I21*G21*N21 | U21: =(2*F21*C21+3*C21)*H21*I21*N21 | V21: =M21*4/1000000000 | W21: =M21*4/1000000000 | X21: =M21*IF(K21="adam8bit",2,8)/1000000000 | Y21: =IF(J21="amp_bf16",M21*2,0)/1000000000 | Z21: =IF(L21="Yes",T21,S21)/1000000000 | AA21: =V21+X21+T21/1000000000 | AB21: =V21+W21+X21+IF(K21="adam",W21,0) | AC21: =V21+X21+Y21+D21*O21*4/1000000000+U21/1000000000+(H21*I21*G21*N21+IF(J21="amp_bf16",H21*I21*G21*4,0))/1000000000 | AD21: =IF(L21="Yes",MAX(AA21,AB21,AC21),V21+W21+X21+Y21+Z21) | AE21: =AD21+0.6+IF(L21="Yes",5.2,1.2) | AF21: =IF(AE21>$C$3,"OOM","fits") | AG21: 20.3462 | AH21: 26.4619 | AI21: =IF(ISNUMBER(AG21),(AD21-AG21)/AG21,"")
A22: checkpointing_seq | B22: 512 | C22: 2048 | D22: 20 | E22: 16 | F22: 4 | G22: 1000 | H22: 256 | I22: 512 | J22: amp_bf16 | K22: adam | L22: Yes | M22: 1011262440 | N22: =IF(J22="amp_bf16",2,4) | O22: =H22*I22*C22 | P22: =H22*I22*F22*C22 | Q22: =9*O22*N22+2*P22*N22+2*O22+P22 | R22: =O22*N22+H22*I22*G22*N22+IF(J22="amp_bf16",H22*I22*G22*4,0) | S22: =Q22*D22+R22 | T22: =(D22+3)*O22*4+7*O22*N22+3*P22*N22+O22+H22*I22*G22*N22 | U22: =(2*F22*C22+3*C22)*H22*I22*N22 | V22: =M22*4/1000000000 | W22: =M22*4/1000000000 | X22: =M22*IF(K22="adam8bit",2,8)/1000000000 | Y22: =IF(J22="amp_bf16",M22*2,0)/1000000000 | Z22: =IF(L22="Yes",T22,S22)/1000000000 | AA22: =V22+X22+T22/1000000000 | AB22: =V22+W22+X22+IF(K22="adam",W22,0) | AC22: =V22+X22+Y22+D22*O22*4/1000000000+U22/1000000000+(H22*I22*G22*N22+IF(J22="amp_bf16",H22*I22*G22*4,0))/1000000000 | AD22: =IF(L22="Yes",MAX(AA22,AB22,AC22),V22+W22+X22+Y22+Z22) | AE22: =AD22+0.6+IF(L22="Yes",5.2,1.2) | AF22: =IF(AE22>$C$3,"OOM","fits") | AG22: 47.7896 | AH22: 51.3697 | AI22: =IF(ISNUMBER(AG22),(AD22-AG22)/AG22,"")
A23: checkpointing_seq | B23: 1024 | C23: 2048 | D23: 20 | E23: 16 | F23: 4 | G23: 1000 | H23: 256 | I23: 1024 | J23: amp_bf16 | K23: adam | L23: Yes | M23: 1010728960 | N23: =IF(J23="amp_bf16",2,4) | O23: =H23*I23*C23 | P23: =H23*I23*F23*C23 | Q23: =9*O23*N23+2*P23*N23+2*O23+P23 | R23: =O23*N23+H23*I23*G23*N23+IF(J23="amp_bf16",H23*I23*G23*4,0) | S23: =Q23*D23+R23 | T23: =(D23+3)*O23*4+7*O23*N23+3*P23*N23+O23+H23*I23*G23*N23 | U23: =(2*F23*C23+3*C23)*H23*I23*N23 | V23: =M23*4/1000000000 | W23: =M23*4/1000000000 | X23: =M23*IF(K23="adam8bit",2,8)/1000000000 | Y23: =IF(J23="amp_bf16",M23*2,0)/1000000000 | Z23: =IF(L23="Yes",T23,S23)/1000000000 | AA23: =V23+X23+T23/1000000000 | AB23: =V23+W23+X23+IF(K23="adam",W23,0) | AC23: =V23+X23+Y23+D23*O23*4/1000000000+U23/1000000000+(H23*I23*G23*N23+IF(J23="amp_bf16",H23*I23*G23*4,0))/1000000000 | AD23: =IF(L23="Yes",MAX(AA23,AB23,AC23),V23+W23+X23+Y23+Z23) | AE23: =AD23+0.6+IF(L23="Yes",5.2,1.2) | AF23: =IF(AE23>$C$3,"OOM","fits") | AG23: OOM | AH23: OOM | AI23: =IF(ISNUMBER(AG23),(AD23-AG23)/AG23,"")
A24: checkpointing_seq | B24: 2048 | C24: 2048 | D24: 20 | E24: 16 | F24: 4 | G24: 1000 | H24: 256 | I24: 2048 | J24: amp_bf16 | K24: adam | L24: Yes | M24: 1010728960 | N24: =IF(J24="amp_bf16",2,4) | O24: =H24*I24*C24 | P24: =H24*I24*F24*C24 | Q24: =9*O24*N24+2*P24*N24+2*O24+P24 | R24: =O24*N24+H24*I24*G24*N24+IF(J24="amp_bf16",H24*I24*G24*4,0) | S24: =Q24*D24+R24 | T24: =(D24+3)*O24*4+7*O24*N24+3*P24*N24+O24+H24*I24*G24*N24 | U24: =(2*F24*C24+3*C24)*H24*I24*N24 | V24: =M24*4/1000000000 | W24: =M24*4/1000000000 | X24: =M24*IF(K24="adam8bit",2,8)/1000000000 | Y24: =IF(J24="amp_bf16",M24*2,0)/1000000000 | Z24: =IF(L24="Yes",T24,S24)/1000000000 | AA24: =V24+X24+T24/1000000000 | AB24: =V24+W24+X24+IF(K24="adam",W24,0) | AC24: =V24+X24+Y24+D24*O24*4/1000000000+U24/1000000000+(H24*I24*G24*N24+IF(J24="amp_bf16",H24*I24*G24*4,0))/1000000000 | AD24: =IF(L24="Yes",MAX(AA24,AB24,AC24),V24+W24+X24+Y24+Z24) | AE24: =AD24+0.6+IF(L24="Yes",5.2,1.2) | AF24: =IF(AE24>$C$3,"OOM","fits") | AG24: OOM | AH24: OOM | AI24: =IF(ISNUMBER(AG24),(AD24-AG24)/AG24,"")
A25: combined | B25: baseline | C25: 2048 | D25: 20 | E25: 16 | F25: 4 | G25: 1000 | H25: 4096 | I25: 2048 | J25: amp_bf16 | K25: adam | L25: No | M25: 1010728960 | N25: =IF(J25="amp_bf16",2,4) | O25: =H25*I25*C25 | P25: =H25*I25*F25*C25 | Q25: =9*O25*N25+2*P25*N25+2*O25+P25 | R25: =O25*N25+H25*I25*G25*N25+IF(J25="amp_bf16",H25*I25*G25*4,0) | S25: =Q25*D25+R25 | T25: =(D25+3)*O25*4+7*O25*N25+3*P25*N25+O25+H25*I25*G25*N25 | U25: =(2*F25*C25+3*C25)*H25*I25*N25 | V25: =M25*4/1000000000 | W25: =M25*4/1000000000 | X25: =M25*IF(K25="adam8bit",2,8)/1000000000 | Y25: =IF(J25="amp_bf16",M25*2,0)/1000000000 | Z25: =IF(L25="Yes",T25,S25)/1000000000 | AA25: =V25+X25+T25/1000000000 | AB25: =V25+W25+X25+IF(K25="adam",W25,0) | AC25: =V25+X25+Y25+D25*O25*4/1000000000+U25/1000000000+(H25*I25*G25*N25+IF(J25="amp_bf16",H25*I25*G25*4,0))/1000000000 | AD25: =IF(L25="Yes",MAX(AA25,AB25,AC25),V25+W25+X25+Y25+Z25) | AE25: =AD25+0.6+IF(L25="Yes",5.2,1.2) | AF25: =IF(AE25>$C$3,"OOM","fits") | AG25: OOM | AH25: OOM | AI25: =IF(ISNUMBER(AG25),(AD25-AG25)/AG25,"")
A26: combined | B26: adam8bit | C26: 2048 | D26: 20 | E26: 16 | F26: 4 | G26: 1000 | H26: 4096 | I26: 2048 | J26: amp_bf16 | K26: adam8bit | L26: No | M26: 1010728960 | N26: =IF(J26="amp_bf16",2,4) | O26: =H26*I26*C26 | P26: =H26*I26*F26*C26 | Q26: =9*O26*N26+2*P26*N26+2*O26+P26 | R26: =O26*N26+H26*I26*G26*N26+IF(J26="amp_bf16",H26*I26*G26*4,0) | S26: =Q26*D26+R26 | T26: =(D26+3)*O26*4+7*O26*N26+3*P26*N26+O26+H26*I26*G26*N26 | U26: =(2*F26*C26+3*C26)*H26*I26*N26 | V26: =M26*4/1000000000 | W26: =M26*4/1000000000 | X26: =M26*IF(K26="adam8bit",2,8)/1000000000 | Y26: =IF(J26="amp_bf16",M26*2,0)/1000000000 | Z26: =IF(L26="Yes",T26,S26)/1000000000 | AA26: =V26+X26+T26/1000000000 | AB26: =V26+W26+X26+IF(K26="adam",W26,0) | AC26: =V26+X26+Y26+D26*O26*4/1000000000+U26/1000000000+(H26*I26*G26*N26+IF(J26="amp_bf16",H26*I26*G26*4,0))/1000000000 | AD26: =IF(L26="Yes",MAX(AA26,AB26,AC26),V26+W26+X26+Y26+Z26) | AE26: =AD26+0.6+IF(L26="Yes",5.2,1.2) | AF26: =IF(AE26>$C$3,"OOM","fits") | AG26: OOM | AH26: OOM | AI26: =IF(ISNUMBER(AG26),(AD26-AG26)/AG26,"")
A27: combined | B27: checkpointing | C27: 2048 | D27: 20 | E27: 16 | F27: 4 | G27: 1000 | H27: 4096 | I27: 2048 | J27: amp_bf16 | K27: adam | L27: Yes | M27: 1010728960 | N27: =IF(J27="amp_bf16",2,4) | O27: =H27*I27*C27 | P27: =H27*I27*F27*C27 | Q27: =9*O27*N27+2*P27*N27+2*O27+P27 | R27: =O27*N27+H27*I27*G27*N27+IF(J27="amp_bf16",H27*I27*G27*4,0) | S27: =Q27*D27+R27 | T27: =(D27+3)*O27*4+7*O27*N27+3*P27*N27+O27+H27*I27*G27*N27 | U27: =(2*F27*C27+3*C27)*H27*I27*N27 | V27: =M27*4/1000000000 | W27: =M27*4/1000000000 | X27: =M27*IF(K27="adam8bit",2,8)/1000000000 | Y27: =IF(J27="amp_bf16",M27*2,0)/1000000000 | Z27: =IF(L27="Yes",T27,S27)/1000000000 | AA27: =V27+X27+T27/1000000000 | AB27: =V27+W27+X27+IF(K27="adam",W27,0) | AC27: =V27+X27+Y27+D27*O27*4/1000000000+U27/1000000000+(H27*I27*G27*N27+IF(J27="amp_bf16",H27*I27*G27*4,0))/1000000000 | AD27: =IF(L27="Yes",MAX(AA27,AB27,AC27),V27+W27+X27+Y27+Z27) | AE27: =AD27+0.6+IF(L27="Yes",5.2,1.2) | AF27: =IF(AE27>$C$3,"OOM","fits") | AG27: OOM | AH27: OOM | AI27: =IF(ISNUMBER(AG27),(AD27-AG27)/AG27,"")
A28: combined | B28: both | C28: 2048 | D28: 20 | E28: 16 | F28: 4 | G28: 1000 | H28: 4096 | I28: 2048 | J28: amp_bf16 | K28: adam8bit | L28: Yes | M28: 1010728960 | N28: =IF(J28="amp_bf16",2,4) | O28: =H28*I28*C28 | P28: =H28*I28*F28*C28 | Q28: =9*O28*N28+2*P28*N28+2*O28+P28 | R28: =O28*N28+H28*I28*G28*N28+IF(J28="amp_bf16",H28*I28*G28*4,0) | S28: =Q28*D28+R28 | T28: =(D28+3)*O28*4+7*O28*N28+3*P28*N28+O28+H28*I28*G28*N28 | U28: =(2*F28*C28+3*C28)*H28*I28*N28 | V28: =M28*4/1000000000 | W28: =M28*4/1000000000 | X28: =M28*IF(K28="adam8bit",2,8)/1000000000 | Y28: =IF(J28="amp_bf16",M28*2,0)/1000000000 | Z28: =IF(L28="Yes",T28,S28)/1000000000 | AA28: =V28+X28+T28/1000000000 | AB28: =V28+W28+X28+IF(K28="adam",W28,0) | AC28: =V28+X28+Y28+D28*O28*4/1000000000+U28/1000000000+(H28*I28*G28*N28+IF(J28="amp_bf16",H28*I28*G28*4,0))/1000000000 | AD28: =IF(L28="Yes",MAX(AA28,AB28,AC28),V28+W28+X28+Y28+Z28) | AE28: =AD28+0.6+IF(L28="Yes",5.2,1.2) | AF28: =IF(AE28>$C$3,"OOM","fits") | AG28: OOM | AH28: OOM | AI28: =IF(ISNUMBER(AG28),(AD28-AG28)/AG28,"")
A29: precision | B29: fp32 | C29: 2048 | D29: 20 | E29: 16 | F29: 4 | G29: 1000 | H29: 256 | I29: 100 | J29: fp32 | K29: adam | L29: No | M29: 1010728960 | N29: =IF(J29="amp_bf16",2,4) | O29: =H29*I29*C29 | P29: =H29*I29*F29*C29 | Q29: =9*O29*N29+2*P29*N29+2*O29+P29 | R29: =O29*N29+H29*I29*G29*N29+IF(J29="amp_bf16",H29*I29*G29*4,0) | S29: =Q29*D29+R29 | T29: =(D29+3)*O29*4+7*O29*N29+3*P29*N29+O29+H29*I29*G29*N29 | U29: =(2*F29*C29+3*C29)*H29*I29*N29 | V29: =M29*4/1000000000 | W29: =M29*4/1000000000 | X29: =M29*IF(K29="adam8bit",2,8)/1000000000 | Y29: =IF(J29="amp_bf16",M29*2,0)/1000000000 | Z29: =IF(L29="Yes",T29,S29)/1000000000 | AA29: =V29+X29+T29/1000000000 | AB29: =V29+W29+X29+IF(K29="adam",W29,0) | AC29: =V29+X29+Y29+D29*O29*4/1000000000+U29/1000000000+(H29*I29*G29*N29+IF(J29="amp_bf16",H29*I29*G29*4,0))/1000000000 | AD29: =IF(L29="Yes",MAX(AA29,AB29,AC29),V29+W29+X29+Y29+Z29) | AE29: =AD29+0.6+IF(L29="Yes",5.2,1.2) | AF29: =IF(AE29>$C$3,"OOM","fits") | AG29: OOM | AH29: OOM | AI29: =IF(ISNUMBER(AG29),(AD29-AG29)/AG29,"")
A31: Largest absolute error across configurations that completed: | F31: =MAX(MAX(AI6:AI29),-MIN(AI6:AI29))
A32: Blue cells are inputs taken verbatim from results.csv. Black cells are calculated by this workbook. Column L 'Checkpointing' was 'True'/'False' in the source file and is written 'Yes'/'No' here to match the Sizing Tool tab. The activation formulas in columns Q and T assume memory-efficient attention (they omit the attention-matrix term that the Sizing Tool's cells B67 and B70 add when its 'Memory-efficient attention' toggle is set to No). Every one of the 24 configurations in this sweep used memory-efficient attention, so the two tabs produce identical numbers for the rows above; they would diverge on the Sizing Tool tab if that toggle were flipped.

Sheet Notes & Sources
A1: Notes and sources
A3: What this workbook models | B3: Peak GPU memory for training one transformer on ONE GPU. Weights, gradients, and optimizer state are stored in FP32 in this training recipe, even when compute precision is BF16 — mixed precision changes the dtype used during the matrix multiplies, not the dtype of stored parameters.
A4: Where the formulas come from | B4: benchmark/predictions.py in github.com/odog96/gpu-sizing-playbook. Plain-arithmetic restatement in articles/1-training/memory-formulas.md, section 6.
A5: Where the measurements come from | B5: benchmark/reference-run/results.csv — a 24-configuration training sweep on a single NVIDIA H100 80GB, varying batch size, sequence length, optimizer, compute precision, and activation checkpointing.
A6: How accurate is it | B6: Against the configurations in that sweep that completed: +2.00% at the baseline (batch 256, sequence 100, hidden 2,048, 20 layers, BF16 mixed precision, standard Adam), +2.17% with 8-bit Adam, and -0.48% to -0.59% on the three that used activation checkpointing. Every configuration that ran out of memory was predicted to.
A7: HIGH confidence — measured | B7: Weights, gradients, and optimizer state: summed directly from real tensors on the device. The 8-bit Adam saving was measured at 6.04 GB against 6.07 GB calculated. The BF16 weight cache was isolated at 1.98 GB measured against 2.02 GB calculated.
A8: HIGH confidence — calculated and validated | B8: The activation formula, both with and without activation checkpointing. The checkpointed version was rebuilt on 2026-07-31 from a CUDA allocator-history replay that identified every live memory block at the peak moment.
A9: SPECULATIVE — the dropout-mask term | B9: The per-layer activation formula assumes three dropout masks are materialised as 1-byte tensors. Some fused CUDA dropout kernels save only the random-number generator state instead, which would make this term zero. It is a small fraction of the total either way.
A10: NOT VALIDATED — memory-efficient attention set to No | B10: The benchmark only ever ran memory-efficient attention. The attention-probability-matrix term this workbook adds when you answer No is calculated from first principles and has never been measured here.
A11: NOT VALIDATED — configurations far from the benchmarked shape | B11: Very large batch sizes, very long sequence lengths, and model sizes well away from 1 billion parameters are formula extrapolations. The formula has no fitted constants, which is a good sign, but it has not been measured at those points.
A12: ESTIMATED — CUDA context and fragmentation | B12: These two allowances translate 'allocated' into 'will this actually fit on a card'. PyTorch's memory API cannot see CUDA context overhead at all. The fragmentation allowances come from the gap between reserved and allocated memory in the sweep: 0.95-1.11 GB without activation checkpointing across two configurations, and 3.58-6.12 GB with it across three. Both are editable on the Sizing Tool tab.
A13: NOT MODELLED — data pipeline memory | B13: These line items account for the model only. GPU-resident data pipelines, RAPIDS and cuDF in particular, can hold significant VRAM outside the model, and for smaller models the pipeline can be the larger consumer. Budget for it separately.
A14: NOT MODELLED — weight quantisation | B14: This workbook covers optimizer-state quantisation, standard Adam against 8-bit Adam. It does not cover storing weights themselves in INT8 or 4-bit, which the benchmark never ran.
... A17: Units | B17: 1 GB = 1,000,000,000 bytes throughout, matching benchmark/predictions.py. Card capacities are advertised in GiB (1,073,741,824 bytes), which is why an '80 GB' card shows about 85 GB of usable capacity here.
