Workbook

Sheet Sizing Tool
A1: GPU Memory Sizing — LoRA Fine-Tuning a Transformer on a Single GPU
A2: Companion tool to Article 2, "Fine-Tuning: What Changes When You Freeze the Base." Fill in the four steps below to size your GPU. Every formula ties back to benchmark/predictions_finetune.py — see the Notes & Sources tab.
A4: YOUR ANSWER — this strip stays visible while you change anything below
A5: TOTAL GPU MEMORY NEEDED (GB) | B5: =Total_Reserved_GB | C5: Size your GPU against this number. It is peak allocated memory plus allocator overhead.
A6: Your GPU's usable capacity (GB) | B6: =Capacity_Used_GB | C6: Set in Step 4 below.
A7: Does this job fit? | B7: =IF(Capacity_Used_GB<=0,"Enter a capacity override in Step 4",IF(Total_Reserved_GB<=Capacity_Used_GB,"FITS","DOES NOT FIT — expect an out-of-memory error"))
A8: Headroom (GB) | B8: =Capacity_Used_GB-Total_Reserved_GB | C8: Negative means you are over capacity by this much.
A9: Card utilization | B9: =IF(Capacity_Used_GB<=0,"",Total_Reserved_GB/Capacity_Used_GB)
A11: LEGEND: blue text on yellow = you edit these | black text = calculated, do not edit | green text = pulled from another tab | grey italic = help text and sources
A13: STEP 1 — YOUR BASE MODEL
A14: Base model | B14: TinyLlama-1.1B (worked model) | C14: Pick from the dropdown. The dropdown covers common LLaMA-family fine-tune targets.
A15: Architecture | B15: ="Hidden dimension "&TEXT(Hidden_Dimension,"#,##0")&" x "&TEXT(Layers,"0")&" layers x "&TEXT(Attention_Heads,"0")&" attention heads / "&TEXT(KV_Heads,"0")&" KV heads (GQA) x FF "&TEXT(FF_Intermediate_Size,"#,##0")&" x vocab "&TEXT(Output_Vocabulary,"#,##0")
A16: Base parameter count | B16: =Base_Parameter_Count | C16: From the preset. Override on the Advanced section if you have a variant.
A17: Base storage precision | B17: BF16 (2 bytes/param) | C17: Standard bf16 loading is 2 bytes per parameter. INT8 (bitsandbytes) is 1 byte. INT4 (QLoRA) is 0.5 bytes. Only the frozen base changes; adapters are always fp32.
A19: STEP 2 — YOUR FINE-TUNE CONFIGURATION
A20: Batch size (rows per batch) | B20: 8 | C20: Examples processed at once. Drives activations linearly.
A21: Sequence length (tokens per example) | B21: 512 | C21: Tokens per example. Drives activations linearly.
A22: Compute precision | B22: BF16 mixed precision | C22: Mixed precision computes in 16-bit. The frozen base uses your Step 1 storage precision. Adapters stay fp32.
A24: STEP 3 — LoRA OPTIONS
A25: LoRA rank (r) | B25: 8 | C25: Typical values 4-64. Adapter parameter count is linear in r. Rank 8 is a good default; the article shows why 8 is 'flat' — everything except adapter/gradient/optimizer is unmoved by rank.
A26: Adapter targets per layer | B26: Attention + MLP (Q, K, V, O, gate, up, down) | C26: Attention-only targets 4 projections per layer. Attention + MLP targets 7 (adds gate, up, down). The formula uses this to compute adapter count.
A27: Adapter placement (which layers) | B27: All layers | C27: Adapters on all layers means every layer's activations must be kept for backward. Upper-N caps this to the top N layers only — the layers below don't save activations. Zero-effect on frozen-weight bytes; the leverage is activation memory.
A28: Optimizer | B28: Standard Adam | C28: 8-bit Adam cuts adapter optimizer state from 8 to 2 bytes per adapter parameter. This is a small saving in absolute terms since adapters are <1% of parameters.
A29: Activation checkpointing | B29: Off | C29: The highest-leverage lever, same as training. Turning it On trades roughly a third more training time for a large drop in activation memory. Under checkpointing the peak becomes the max of three phase peaks, not their sum.
A31: STEP 4 — YOUR HARDWARE
A32: GPU | B32: NVIDIA H100 80GB | C32: One GPU. Multi-GPU strategies are a later article in the series.
A33: Usable capacity after driver reserve (GB) | B33: =INDEX('GPU Capacity'!$C$5:$C$16,MATCH(GPU_Choice,'GPU Capacity'!$A$5:$A$16,0)) | C33: From the GPU Capacity tab.
A34: Your capacity override (GB) | C34: Fill this in if your card is not in the list, or you want to reserve capacity for something else.
A35: Capacity used in this calculation (GB) | B35: =IF(GPU_Capacity_Override_GB="",GPU_Usable_Capacity_GB,GPU_Capacity_Override_GB)
A37: RESULT — THE SEVEN LINE ITEMS (GB)
A38: Line item | B38: Memory (GB) | C38: What drives it | D38: Source in benchmark/predictions_finetune.py
A39: Frozen base weights | B39: =Base_Parameter_Count*Base_Storage_Bytes_Per_Param/1000000000 | C39: Parameter count x storage bytes. Storage depends on Step 1 (bf16=2, int8=1, int4=0.5). No gradient stored — the base is frozen. | D39: predict_frozen_weights_bytes()
A40: Adapter weights | B40: =Adapter_Parameter_Count*4/1000000000 | C40: LoRA adapters kept in fp32 regardless of Step 2 precision — the small updates would otherwise get rounded away. | D40: predict_adapter_weights_bytes()
A41: Adapter gradients | B41: =Adapter_Parameter_Count*4/1000000000 | C41: One gradient per trainable parameter, fp32. Frozen base has no gradient. | D41: predict_adapter_gradients_bytes()
A42: Adapter optimizer state | B42: =Adapter_Parameter_Count*Optimizer_Bytes_Per_Adapter_Param/1000000000 | C42: Standard Adam: 8 bytes per adapter parameter. 8-bit Adam: 2 bytes. Same arithmetic as training, applied to <1% of the parameter count. | D42: predict_adapter_optimizer_bytes()
A43: Autocast weight cache | B43: =IF(Compute_Precision="BF16 mixed precision",IF(Base_Storage_Precision="FP32 (4 bytes/param)",(Base_Parameter_Count+Adapter_Parameter_Count)*2,Adapter_Parameter_Count*2),0)/1000000000 | C43: Under bf16 autocast PyTorch caches a bf16 copy of each fp32 weight it casts. Base is loaded at bf16 directly, so this collapses to the adapter-only residual — megabytes at rank 8. Article 1's ~n_params*2 term only reappears if the base is loaded fp32. | D43: predict_autocast_weight_cache_bytes()
A44: Activations | B44: =IF(Activation_Checkpointing="On",Activations_Ckpt_On_Bytes,Activations_Ckpt_Off_Bytes)/1000000000 | C44: The dynamic line item. Scales with batch x sequence x number of layers needing backward. Adapter placement scales this directly. | D44: predict_activation_bytes()
A45: Matrix-multiply workspace (cuBLAS) | B45: =IF(Activation_Checkpointing="On",0,cuBLAS_Workspace_Bytes)/1000000000 | C45: cuBLAS caches GEMM workspace buffers per matmul shape. Empirically: K = 4.316 + 1.871 x L_bwd workspaces of size batch x seq x d x 4 bytes. Under checkpointing the allocator pressure forces cuBLAS to release these between segments, so this is zero. | D45: predict_cublas_workspace_bytes()
A46: PEAK ALLOCATED (GB) | B46: =IF(Activation_Checkpointing="On",MAX(Phase_Peak_Backward_GB,Phase_Peak_Optimizer_Step_GB,Phase_Peak_Forward_GB),Frozen_Base_Weights_GB+Adapter_Weights_GB+Adapter_Gradients_GB+Adapter_Optimizer_State_GB+Autocast_Weight_Cache_GB+Activations_GB+MatMul_Workspace_GB) | D46: predict_line_items_finetune()
A47: Allocator overhead — CUDA context plus fragmentation (GB) | B47: =CUDA_Context_GB+IF(Activation_Checkpointing="On",Fragmentation_Ckpt_On_GB,Fragmentation_Ckpt_Off_GB) | D47: predictions_finetune.py — CUDA_CONTEXT_GB + FRAGMENTATION_GB
...

Sheet Model Presets
A1: Architecture presets — pick a model on the Sizing Tool tab and these fill in automatically
A2: Every model here is a LLaMA-family decoder-only transformer with GQA (grouped-query attention) and a SwiGLU MLP. You never have to know these numbers to use the tool. Override any of them in the Sizing Tool's Advanced section.
A4: Preset | B4: Hidden dim (d) | C4: Layers | D4: Heads | E4: KV heads (GQA) | F4: FF intermediate size | G4: Vocabulary | H4: Base param count | I4: Source of shapes
A5: TinyLlama-1.1B (worked model) | B5: 2048 | C5: 22 | D5: 32 | E5: 4 | F5: 5632 | G5: 32000 | H5: 1100048384 | I5: Exact architecture benchmarked in benchmark/reference-run/results_finetune.csv
A6: LLaMA-2-7B | B6: 4096 | C6: 32 | D6: 32 | E6: 32 | F6: 11008 | G6: 32000 | H6: 6738415616 | I6: HuggingFace meta-llama/Llama-2-7b-hf config
A7: LLaMA-3-8B | B7: 4096 | C7: 32 | D7: 32 | E7: 8 | F7: 14336 | G7: 128256 | H7: 8030261248 | I7: HuggingFace meta-llama/Meta-Llama-3-8B config
A8: Mistral-7B-v0.1 | B8: 4096 | C8: 32 | D8: 32 | E8: 8 | F8: 14336 | G8: 32000 | H8: 7241732096 | I8: HuggingFace mistralai/Mistral-7B-v0.1 config
A9: LLaMA-2-13B | B9: 5120 | C9: 40 | D9: 40 | E9: 40 | F9: 13824 | G9: 32000 | H9: 13015864320 | I9: HuggingFace meta-llama/Llama-2-13b-hf config
A10: LLaMA-2-70B | B10: 8192 | C10: 80 | D10: 64 | E10: 8 | F10: 28672 | G10: 32000 | H10: 68976648192 | I10: HuggingFace meta-llama/Llama-2-70b-hf config
A12: Only TinyLlama-1.1B has direct benchmark validation. The other five are predictions-only — the formula extrapolates cleanly (adapter parameter count, cuBLAS count, autocast cache all scale from these shapes) but no measured evidence yet at these sizes.
A14: Dropdown list — adapter targets per layer (referenced by the Sizing Tool tab; do not edit)
A15: Attention (Q, K, V, O)
A16: Attention + MLP (Q, K, V, O, gate, up, down)

Sheet GPU Capacity
A1: GPU usable capacity
A2: Units are decimal GB (1 GB = 1,000,000,000 bytes) throughout this workbook, matching benchmark/predictions_finetune.py. A card's advertised size in GiB is converted here to decimal GB and reduced by ~1% for driver reserve.
A4: GPU | B4: Advertised size (GiB) | C4: Usable capacity (GB, decimal) | D4: Basis
A5: NVIDIA H100 80GB | B5: 80 | C5: =79.18*1024^3/1000000000 | D5: Measured — torch reported 79.18 GiB usable in the fine-tune sweep's OOM messages
A6: NVIDIA A100 80GB | B6: 80 | C6: =79.18*1024^3/1000000000 | D6: Estimated — same 80 GiB class as the measured H100 row above
A7: NVIDIA A100 40GB | B7: 40 | C7: =B7*1024^3/1000000000*0.99 | D7: Estimated — advertised size less 1% for driver reserve
A8: NVIDIA L40S 48GB | B8: 48 | C8: =B8*1024^3/1000000000*0.99 | D8: Estimated — advertised size less 1% for driver reserve
A9: NVIDIA RTX PRO 6000 Blackwell 96GB | B9: 96 | C9: =B9*1024^3/1000000000*0.99 | D9: Estimated — advertised size less 1% for driver reserve
A10: NVIDIA A10G 24GB | B10: 24 | C10: =B10*1024^3/1000000000*0.99 | D10: Estimated — advertised size less 1% for driver reserve
A11: NVIDIA RTX 4090 24GB | B11: 24 | C11: =B11*1024^3/1000000000*0.99 | D11: Estimated — advertised size less 1% for driver reserve
A12: NVIDIA H200 141GB | B12: 141 | C12: =B12*1024^3/1000000000*0.99 | D12: Estimated — advertised size less 1% for driver reserve
A13: NVIDIA B200 180GB | B13: 180 | C13: =B13*1024^3/1000000000*0.99 | D13: Estimated — advertised size less 1% for driver reserve
A14: NVIDIA H100 NVL 94GB | B14: 94 | C14: =B14*1024^3/1000000000*0.99 | D14: Estimated — advertised size less 1% for driver reserve
A15: NVIDIA RTX 6000 Ada 48GB | B15: 48 | C15: =B15*1024^3/1000000000*0.99 | D15: Estimated — advertised size less 1% for driver reserve
A16: Other — use the override cell on the Sizing Tool tab | B16: 0 | C16: =0 | D16: Enter your own usable capacity on the Sizing Tool tab

Sheet Validation
A1: Validation — the same formulas, run against the v3 H100 fine-tune sweep
A2: Every prediction column is computed by benchmark/predictions_finetune.py; measured columns come from runs/finetune-20260817-v3-finetune/results_finetune.csv. All 23 non-OOM rows land within +/-10% of measured max_allocated; the 2 boundary OOM misses are reported honestly, following Article 1's precedent.
A3: Every column on this tab is imported verbatim from benchmark/reference-run-finetune/results_finetune.csv — nothing here is recalculated by the workbook. | B3: Usable capacity used for the OOM call (GB): | C3: =79.18*1024^3/1000000000
A5: lever | B5: lever_value | C5: base_model_name | D5: base_storage_precision | E5: lora_rank | F5: lora_target_modules | G5: lora_adapter_layers | H5: batch | I5: seq_len | J5: precision | K5: optimizer | L5: checkpointing | M5: steps | N5: hidden_size | O5: num_hidden_layers | P5: num_attention_heads | Q5: num_key_value_heads | R5: intermediate_size | S5: vocab_size | T5: n_frozen_params | U5: n_trainable_params | V5: n_layers_needing_backward | W5: predicted_frozen_weights_gb | X5: predicted_adapter_weights_gb | Y5: predicted_gradients_gb | Z5: predicted_optimizer_gb | AA5: predicted_autocast_weight_cache_gb | AB5: predicted_activations_gb | AC5: predicted_allocated_gb | AD5: predicted_reserved_gb | AE5: predicted_oom | AF5: oom | AG5: max_allocated_gb | AH5: max_reserved_gb | AI5: ratio | AJ5: measured_param_bytes | AK5: measured_frozen_param_bytes | AL5: measured_trainable_param_bytes | AM5: measured_grad_bytes | AN5: measured_optimizer_bytes | AO5: alloc_after_model_gb | AP5: alloc_after_optimizer_gb | AQ5: peak_forward_gb | AR5: measured_activations_gb | AS5: wall_time_s | AT5: step_time_mean_ms | AU5: step_time_median_ms | AV5: final_loss
A6: baseline | B6: baseline | C6: TinyLlama/TinyLlama-1.1B-intermediate-step-1431k-3T | D6: bf16 | E6: 8 | F6: q_proj|k_proj|v_proj|o_proj|gate_proj|up_proj|down_proj | G6: all | H6: 8 | I6: 512 | J6: amp_bf16 | K6: adam | L6: False | M6: 7 | N6: 2048 | O6: 22 | P6: 32 | Q6: 4 | R6: 5632 | S6: 32000 | T6: 1100048384 | U6: 6307840 | V6: 22 | W6: 2.2001 | X6: 0.0252 | Y6: 0.0252 | Z6: 0.0505 | AA6: 0.0126 | AB6: 8.9569 | AC6: 12.7966 | AD6: 14.5966 | AE6: False | AF6: False | AG6: 12.7966 | AH6: 14.4934 | AI6: 1 | AJ6: 2225328128 | AK6: 2200096768 | AL6: 25231360 | AM6: 25231360 | AN6: 50463952 | AO6: 2.2274 | AP6: 2.7247 | AQ6: 12.6437 | AR6: 10.0719 | AS6: 5.93 | AT6: 108.303 | AU6: 108.299 | AV6: 11.4606
A7: batch_size | B7: 4 | C7: TinyLlama/TinyLlama-1.1B-intermediate-step-1431k-3T | D7: bf16 | E7: 8 | F7: q_proj|k_proj|v_proj|o_proj|gate_proj|up_proj|down_proj | G7: all | H7: 4 | I7: 512 | J7: amp_bf16 | K7: adam | L7: False | M7: 7 | N7: 2048 | O7: 22 | P7: 32 | Q7: 4 | R7: 5632 | S7: 32000 | T7: 1100048384 | U7: 6307840 | V7: 22 | W7: 2.2001 | X7: 0.0252 | Y7: 0.0252 | Z7: 0.0505 | AA7: 0.0126 | AB7: 4.4785 | AC7: 7.5551 | AD7: 9.3551 | AE7: False | AF7: False | AG7: 7.5782 | AH7: 8.785 | AI7: 1.003 | AJ7: 2225328128 | AK7: 2200096768 | AL7: 25231360 | AM7: 25231360 | AN7: 50463952 | AO7: 2.2274 | AP7: 2.5485 | AQ7: 7.5018 | AR7: 5.0297 | AS7: 5.539 | AT7: 76.293 | AU7: 76.115 | AV7: 11.4613
A8: batch_size | B8: 8 | C8: TinyLlama/TinyLlama-1.1B-intermediate-step-1431k-3T | D8: bf16 | E8: 8 | F8: q_proj|k_proj|v_proj|o_proj|gate_proj|up_proj|down_proj | G8: all | H8: 8 | I8: 512 | J8: amp_bf16 | K8: adam | L8: False | M8: 7 | N8: 2048 | O8: 22 | P8: 32 | Q8: 4 | R8: 5632 | S8: 32000 | T8: 1100048384 | U8: 6307840 | V8: 22 | W8: 2.2001 | X8: 0.0252 | Y8: 0.0252 | Z8: 0.0505 | AA8: 0.0126 | AB8: 8.9569 | AC8: 12.7966 | AD8: 14.5966 | AE8: False | AF8: False | AG8: 12.7966 | AH8: 14.4934 | AI8: 1 | AJ8: 2225328128 | AK8: 2200096768 | AL8: 25231360 | AM8: 25231360 | AN8: 50463952 | AO8: 2.2274 | AP8: 2.7247 | AQ8: 12.6437 | AR8: 10.0719 | AS8: 5.898 | AT8: 108.858 | AU8: 108.843 | AV8: 11.4605
A9: batch_size | B9: 16 | C9: TinyLlama/TinyLlama-1.1B-intermediate-step-1431k-3T | D9: bf16 | E9: 8 | F9: q_proj|k_proj|v_proj|o_proj|gate_proj|up_proj|down_proj | G9: all | H9: 16 | I9: 512 | J9: amp_bf16 | K9: adam | L9: False | M9: 7 | N9: 2048 | O9: 22 | P9: 32 | Q9: 4 | R9: 5632 | S9: 32000 | T9: 1100048384 | U9: 6307840 | V9: 22 | W9: 2.2001 | X9: 0.0252 | Y9: 0.0252 | Z9: 0.0505 | AA9: 0.0126 | AB9: 17.9139 | AC9: 23.2795 | AD9: 25.0795 | AE9: False | AF9: False | AG9: 23.2356 | AH9: 26.5332 | AI9: 0.998 | AJ9: 2225328128 | AK9: 2200096768 | AL9: 25231360 | AM9: 25231360 | AN9: 50463952 | AO9: 2.2274 | AP9: 3.0792 | AQ9: 22.9297 | AR9: 20.1564 | AS9: 6.522 | AT9: 206.22 | AU9: 206.228 | AV9: 11.4325
A10: batch_size | B10: 32 | C10: TinyLlama/TinyLlama-1.1B-intermediate-step-1431k-3T | D10: bf16 | E10: 8 | F10: q_proj|k_proj|v_proj|o_proj|gate_proj|up_proj|down_proj | G10: all | H10: 32 | I10: 512 | J10: amp_bf16 | K10: adam | L10: False | M10: 7 | N10: 2048 | O10: 22 | P10: 32 | Q10: 4 | R10: 5632 | S10: 32000 | T10: 1100048384 | U10: 6307840 | V10: 22 | W10: 2.2001 | X10: 0.0252 | Y10: 0.0252 | Z10: 0.0505 | AA10: 0.0126 | AB10: 35.8277 | AC10: 44.2453 | AD10: 46.0453 | AE10: False | AF10: False | AG10: 44.1135 | AH10: 50.6378 | AI10: 0.997 | AJ10: 2225328128 | AK10: 2200096768 | AL10: 25231360 | AM10: 25231360 | AN10: 50463952 | AO10: 2.2274 | AP10: 3.7882 | AQ10: 43.5015 | AR10: 40.3254 | AS10: 8.095 | AT10: 391.175 | AU10: 391.169 | AV10: 11.4263
A11: seq_len | B11: 256 | C11: TinyLlama/TinyLlama-1.1B-intermediate-step-1431k-3T | D11: bf16 | E11: 8 | F11: q_proj|k_proj|v_proj|o_proj|gate_proj|up_proj|down_proj | G11: all | H11: 8 | I11: 256 | J11: amp_bf16 | K11: adam | L11: False | M11: 7 | N11: 2048 | O11: 22 | P11: 32 | Q11: 4 | R11: 5632 | S11: 32000 | T11: 1100048384 | U11: 6307840 | V11: 22 | W11: 2.2001 | X11: 0.0252 | Y11: 0.0252 | Z11: 0.0505 | AA11: 0.0126 | AB11: 4.4785 | AC11: 7.5551 | AD11: 9.3551 | AE11: False | AF11: False | AG11: 7.5781 | AH11: 8.785 | AI11: 1.003 | AJ11: 2225328128 | AK11: 2200096768 | AL11: 25231360 | AM11: 25231360 | AN11: 50463952 | AO11: 2.2274 | AP11: 2.5485 | AQ11: 7.5017 | AR11: 5.0296 | AS11: 5.679 | AT11: 78.471 | AU11: 78.674 | AV11: 11.5837
A12: seq_len | B12: 512 | C12: TinyLlama/TinyLlama-1.1B-intermediate-step-1431k-3T | D12: bf16 | E12: 8 | F12: q_proj|k_proj|v_proj|o_proj|gate_proj|up_proj|down_proj | G12: all | H12: 8 | I12: 512 | J12: amp_bf16 | K12: adam | L12: False | M12: 7 | N12: 2048 | O12: 22 | P12: 32 | Q12: 4 | R12: 5632 | S12: 32000 | T12: 1100048384 | U12: 6307840 | V12: 22 | W12: 2.2001 | X12: 0.0252 | Y12: 0.0252 | Z12: 0.0505 | AA12: 0.0126 | AB12: 8.9569 | AC12: 12.7966 | AD12: 14.5966 | AE12: False | AF12: False | AG12: 12.7966 | AH12: 14.4934 | AI12: 1 | AJ12: 2225328128 | AK12: 2200096768 | AL12: 25231360 | AM12: 25231360 | AN12: 50463952 | AO12: 2.2274 | AP12: 2.7247 | AQ12: 12.6437 | AR12: 10.0719 | AS12: 5.878 | AT12: 108.281 | AU12: 108.29 | AV12: 11.4603
A13: seq_len | B13: 1024 | C13: TinyLlama/TinyLlama-1.1B-intermediate-step-1431k-3T | D13: bf16 | E13: 8 | F13: q_proj|k_proj|v_proj|o_proj|gate_proj|up_proj|down_proj | G13: all | H13: 8 | I13: 1024 | J13: amp_bf16 | K13: adam | L13: False | M13: 7 | N13: 2048 | O13: 22 | P13: 32 | Q13: 4 | R13: 5632 | S13: 32000 | T13: 1100048384 | U13: 6307840 | V13: 22 | W13: 2.2001 | X13: 0.0252 | Y13: 0.0252 | Z13: 0.0505 | AA13: 0.0126 | AB13: 17.9139 | AC13: 23.2795 | AD13: 25.0795 | AE13: False | AF13: False | AG13: 23.2357 | AH13: 26.5353 | AI13: 0.998 | AJ13: 2225328128 | AK13: 2200096768 | AL13: 25231360 | AM13: 25231360 | AN13: 50463952 | AO13: 2.2274 | AP13: 3.0792 | AQ13: 22.9298 | AR13: 20.1565 | AS13: 6.564 | AT13: 208.197 | AU13: 208.197 | AV13: 11.3545
A14: seq_len | B14: 2048 | C14: TinyLlama/TinyLlama-1.1B-intermediate-step-1431k-3T | D14: bf16 | E14: 8 | F14: q_proj|k_proj|v_proj|o_proj|gate_proj|up_proj|down_proj | G14: all | H14: 8 | I14: 2048 | J14: amp_bf16 | K14: adam | L14: False | M14: 7 | N14: 2048 | O14: 22 | P14: 32 | Q14: 4 | R14: 5632 | S14: 32000 | T14: 1100048384 | U14: 6307840 | V14: 22 | W14: 2.2001 | X14: 0.0252 | Y14: 0.0252 | Z14: 0.0505 | AA14: 0.0126 | AB14: 35.8277 | AC14: 44.2453 | AD14: 46.0453 | AE14: False | AF14: False | AG14: 44.1139 | AH14: 50.6378 | AI14: 0.997 | AJ14: 2225328128 | AK14: 2200096768 | AL14: 25231360 | AM14: 25231360 | AN14: 50463952 | AO14: 2.2274 | AP14: 3.7882 | AQ14: 43.5019 | AR14: 40.3258 | AS14: 8.175 | AT14: 408.248 | AU14: 408.247 | AV14: 11.3208
A15: lora_rank | B15: 4 | C15: TinyLlama/TinyLlama-1.1B-intermediate-step-1431k-3T | D15: bf16 | E15: 4 | F15: q_proj|k_proj|v_proj|o_proj|gate_proj|up_proj|down_proj | G15: all | H15: 8 | I15: 512 | J15: amp_bf16 | K15: adam | L15: False | M15: 7 | N15: 2048 | O15: 22 | P15: 32 | Q15: 4 | R15: 5632 | S15: 32000 | T15: 1100048384 | U15: 3153920 | V15: 22 | W15: 2.2001 | X15: 0.0126 | Y15: 0.0126 | Z15: 0.0252 | AA15: 0.0063 | AB15: 8.9569 | AC15: 12.7398 | AD15: 14.5398 | AE15: False | AF15: False | AG15: 12.7475 | AH15: 14.4305 | AI15: 1.001 | AJ15: 2212712448 | AK15: 2200096768 | AL15: 12615680 | AM15: 12615680 | AN15: 25232592 | AO15: 2.2148 | AP15: 2.6743 | AQ15: 12.5945 | AR15: 10.0732 | AS15: 5.849 | AT15: 112.702 | AU15: 112.718 | AV15: 11.7348
A16: lora_rank | B16: 8 | C16: TinyLlama/TinyLlama-1.1B-intermediate-step-1431k-3T | D16: bf16 | E16: 8 | F16: q_proj|k_proj|v_proj|o_proj|gate_proj|up_proj|down_proj | G16: all | H16: 8 | I16: 512 | J16: amp_bf16 | K16: adam | L16: False | M16: 7 | N16: 2048 | O16: 22 | P16: 32 | Q16: 4 | R16: 5632 | S16: 32000 | T16: 1100048384 | U16: 6307840 | V16: 22 | W16: 2.2001 | X16: 0.0252 | Y16: 0.0252 | Z16: 0.0505 | AA16: 0.0126 | AB16: 8.9569 | AC16: 12.7966 | AD16: 14.5966 | AE16: False | AF16: False | AG16: 12.7966 | AH16: 14.4934 | AI16: 1 | AJ16: 2225328128 | AK16: 2200096768 | AL16: 25231360 | AM16: 25231360 | AN16: 50463952 | AO16: 2.2274 | AP16: 2.7247 | AQ16: 12.6437 | AR16: 10.0719 | AS16: 5.754 | AT16: 108.264 | AU16: 108.25 | AV16: 11.4602
A17: lora_rank | B17: 16 | C17: TinyLlama/TinyLlama-1.1B-intermediate-step-1431k-3T | D17: bf16 | E17: 16 | F17: q_proj|k_proj|v_proj|o_proj|gate_proj|up_proj|down_proj | G17: all | H17: 8 | I17: 512 | J17: amp_bf16 | K17: adam | L17: False | M17: 7 | N17: 2048 | O17: 22 | P17: 32 | Q17: 4 | R17: 5632 | S17: 32000 | T17: 1100048384 | U17: 12615680 | V17: 22 | W17: 2.2001 | X17: 0.0505 | Y17: 0.0505 | Z17: 0.1009 | AA17: 0.0252 | AB17: 8.9569 | AC17: 12.9101 | AD17: 14.7101 | AE17: False | AF17: False | AG17: 12.8949 | AH17: 14.6255 | AI17: 0.999 | AJ17: 2250559488 | AK17: 2200096768 | AL17: 50462720 | AM17: 50462720 | AN17: 100926672 | AO17: 2.2527 | AP17: 2.8256 | AQ17: 12.7421 | AR17: 10.0693 | AS17: 5.897 | AT17: 108.82 | AU17: 108.794 | AV17: 11.1993
A18: lora_rank | B18: 64 | C18: TinyLlama/TinyLlama-1.1B-intermediate-step-1431k-3T | D18: bf16 | E18: 64 | F18: q_proj|k_proj|v_proj|o_proj|gate_proj|up_proj|down_proj | G18: all | H18: 8 | I18: 512 | J18: amp_bf16 | K18: adam | L18: False | M18: 7 | N18: 2048 | O18: 22 | P18: 32 | Q18: 4 | R18: 5632 | S18: 32000 | T18: 1100048384 | U18: 50462720 | V18: 22 | W18: 2.2001 | X18: 0.2019 | Y18: 0.2019 | Z18: 0.4037 | AA18: 0.1009 | AB18: 8.9569 | AC18: 13.5914 | AD18: 15.3914 | AE18: False | AF18: False | AG18: 13.4996 | AH18: 14.9674 | AI18: 0.993 | AJ18: 2401947648 | AK18: 2200096768 | AL18: 201850880 | AM18: 201850880 | AN18: 403702992 | AO18: 2.4072 | AP18: 3.4506 | AQ18: 13.3467 | AR18: 10.049 | AS18: 6.251 | AT18: 108.925 | AU18: 108.92 | AV18: 10.7989
A19: checkpointing | B19: False | C19: TinyLlama/TinyLlama-1.1B-intermediate-step-1431k-3T | D19: bf16 | E19: 8 | F19: q_proj|k_proj|v_proj|o_proj|gate_proj|up_proj|down_proj | G19: all | H19: 8 | I19: 512 | J19: amp_bf16 | K19: adam | L19: False | M19: 7 | N19: 2048 | O19: 22 | P19: 32 | Q19: 4 | R19: 5632 | S19: 32000 | T19: 1100048384 | U19: 6307840 | V19: 22 | W19: 2.2001 | X19: 0.0252 | Y19: 0.0252 | Z19: 0.0505 | AA19: 0.0126 | AB19: 8.9569 | AC19: 12.7966 | AD19: 14.5966 | AE19: False | AF19: False | AG19: 12.7966 | AH19: 14.4934 | AI19: 1 | AJ19: 2225328128 | AK19: 2200096768 | AL19: 25231360 | AM19: 25231360 | AN19: 50463952 | AO19: 2.2274 | AP19: 2.7247 | AQ19: 12.6437 | AR19: 10.0719 | AS19: 6.097 | AT19: 108.85 | AU19: 108.838 | AV19: 11.4604
A20: checkpointing | B20: True | C20: TinyLlama/TinyLlama-1.1B-intermediate-step-1431k-3T | D20: bf16 | E20: 8 | F20: q_proj|k_proj|v_proj|o_proj|gate_proj|up_proj|down_proj | G20: all | H20: 8 | I20: 512 | J20: amp_bf16 | K20: adam | L20: True | M20: 7 | N20: 2048 | O20: 22 | P20: 32 | Q20: 4 | R20: 5632 | S20: 32000 | T20: 1100048384 | U20: 6307840 | V20: 22 | W20: 2.2001 | X20: 0.0252 | Y20: 0.0252 | Z20: 0.0505 | AA20: 0.0126 | AB20: 2.439 | AC20: 4.7148 | AD20: 10.5148 | AE20: False | AF20: False | AG20: 4.5829 | AH20: 5.5679 | AI20: 0.972 | AJ20: 2225328128 | AK20: 2200096768 | AL20: 25231360 | AM20: 25231360 | AN20: 50463952 | AO20: 2.2274 | AP20: 2.666 | AQ20: 4.3837 | AR20: 1.9169 | AS20: 6.278 | AT20: 150.019 | AU20: 149.993 | AV20: 11.4603
A21: adapter_placement | B21: all | C21: TinyLlama/TinyLlama-1.1B-intermediate-step-1431k-3T | D21: bf16 | E21: 8 | F21: q_proj|k_proj|v_proj|o_proj|gate_proj|up_proj|down_proj | G21: all | H21: 8 | I21: 512 | J21: amp_bf16 | K21: adam | L21: False | M21: 7 | N21: 2048 | O21: 22 | P21: 32 | Q21: 4 | R21: 5632 | S21: 32000 | T21: 1100048384 | U21: 6307840 | V21: 22 | W21: 2.2001 | X21: 0.0252 | Y21: 0.0252 | Z21: 0.0505 | AA21: 0.0126 | AB21: 8.9569 | AC21: 12.7966 | AD21: 14.5966 | AE21: False | AF21: False | AG21: 12.7966 | AH21: 14.4934 | AI21: 1 | AJ21: 2225328128 | AK21: 2200096768 | AL21: 25231360 | AM21: 25231360 | AN21: 50463952 | AO21: 2.2274 | AP21: 2.7247 | AQ21: 12.6437 | AR21: 10.0719 | AS21: 5.841 | AT21: 108.198 | AU21: 108.157 | AV21: 11.4606
A22: adapter_placement | B22: upper-11 | C22: TinyLlama/TinyLlama-1.1B-intermediate-step-1431k-3T | D22: bf16 | E22: 8 | F22: q_proj|k_proj|v_proj|o_proj|gate_proj|up_proj|down_proj | G22: upper-11 | H22: 8 | I22: 512 | J22: amp_bf16 | K22: adam | L22: False | M22: 7 | N22: 2048 | O22: 22 | P22: 32 | Q22: 4 | R22: 5632 | S22: 32000 | T22: 1100048384 | U22: 3153920 | V22: 11 | W22: 2.2001 | X22: 0.0126 | Y22: 0.0126 | Z22: 0.0252 | AA22: 0.0063 | AB22: 5.4044 | AC22: 8.4966 | AD22: 10.2966 | AE22: False | AF22: False | AG22: 8.4967 | AH22: 9.4603 | AI22: 1 | AJ22: 2212712448 | AK22: 2200096768 | AL22: 12615680 | AM22: 12615680 | AN22: 25231976 | AO22: 2.2148 | AP22: 2.6743 | AQ22: 8.3437 | AR22: 5.8224 | AS22: 5.562 | AT22: 68.063 | AU22: 68.034 | AV22: 11.5915
A23: adapter_placement | B23: upper-6 | C23: TinyLlama/TinyLlama-1.1B-intermediate-step-1431k-3T | D23: bf16 | E23: 8 | F23: q_proj|k_proj|v_proj|o_proj|gate_proj|up_proj|down_proj | G23: upper-6 | H23: 8 | I23: 512 | J23: amp_bf16 | K23: adam | L23: False | M23: 7 | N23: 2048 | O23: 22 | P23: 32 | Q23: 4 | R23: 5632 | S23: 32000 | T23: 1100048384 | U23: 1720320 | V23: 6 | W23: 2.2001 | X23: 0.0069 | Y23: 0.0069 | Z23: 0.0138 | AA23: 0.0034 | AB23: 3.7896 | AC23: 6.5421 | AD23: 8.3421 | AE23: False | AF23: False | AG23: 6.5421 | AH23: 7.3967 | AI23: 1 | AJ23: 2206978048 | AK23: 2200096768 | AL23: 6881280 | AM23: 6881280 | AN23: 13762896 | AO23: 2.2091 | AP23: 2.6513 | AQ23: 6.3892 | AR23: 3.8908 | AS23: 5.398 | AT23: 50 | AU23: 49.945 | AV23: 11.9112
A24: adapter_placement | B24: upper-3 | C24: TinyLlama/TinyLlama-1.1B-intermediate-step-1431k-3T | D24: bf16 | E24: 8 | F24: q_proj|k_proj|v_proj|o_proj|gate_proj|up_proj|down_proj | G24: upper-3 | H24: 8 | I24: 512 | J24: amp_bf16 | K24: adam | L24: False | M24: 7 | N24: 2048 | O24: 22 | P24: 32 | Q24: 4 | R24: 5632 | S24: 32000 | T24: 1100048384 | U24: 860160 | V24: 3 | W24: 2.2001 | X24: 0.0034 | Y24: 0.0034 | Z24: 0.0069 | AA24: 0.0017 | AB24: 2.8207 | AC24: 5.3694 | AD24: 7.1694 | AE24: False | AF24: False | AG24: 5.3694 | AH24: 6.1572 | AI24: 1 | AJ24: 2203537408 | AK24: 2200096768 | AL24: 3440640 | AM24: 3440640 | AN24: 6881448 | AO24: 2.2056 | AP24: 2.6376 | AQ24: 5.2165 | AR24: 2.7319 | AS24: 5.12 | AT24: 39.364 | AU24: 39.371 | AV24: 12.0899
A25: base_precision | B25: bf16 | C25: TinyLlama/TinyLlama-1.1B-intermediate-step-1431k-3T | D25: bf16 | E25: 8 | F25: q_proj|k_proj|v_proj|o_proj|gate_proj|up_proj|down_proj | G25: all | H25: 8 | I25: 512 | J25: amp_bf16 | K25: adam | L25: False | M25: 7 | N25: 2048 | O25: 22 | P25: 32 | Q25: 4 | R25: 5632 | S25: 32000 | T25: 1100048384 | U25: 6307840 | V25: 22 | W25: 2.2001 | X25: 0.0252 | Y25: 0.0252 | Z25: 0.0505 | AA25: 0.0126 | AB25: 8.9569 | AC25: 12.7966 | AD25: 14.5966 | AE25: False | AF25: False | AG25: 12.7966 | AH25: 14.4934 | AI25: 1 | AJ25: 2225328128 | AK25: 2200096768 | AL25: 25231360 | AM25: 25231360 | AN25: 50463952 | AO25: 2.2274 | AP25: 2.7247 | AQ25: 12.6437 | AR25: 10.0719 | AS25: 5.989 | AT25: 109.031 | AU25: 109.036 | AV25: 11.4603
A26: base_precision | B26: fp32 | C26: TinyLlama/TinyLlama-1.1B-intermediate-step-1431k-3T | D26: fp32 | E26: 8 | F26: q_proj|k_proj|v_proj|o_proj|gate_proj|up_proj|down_proj | G26: all | H26: 8 | I26: 512 | J26: amp_bf16 | K26: adam | L26: False | M26: 7 | N26: 2048 | O26: 22 | P26: 32 | Q26: 4 | R26: 5632 | S26: 32000 | T26: 1100048384 | U26: 6307840 | V26: 22 | W26: 4.4002 | X26: 0.0252 | Y26: 0.0252 | Z26: 0.0505 | AA26: 2.2127 | AB26: 8.9569 | AC26: 17.1968 | AD26: 18.9968 | AE26: False | AF26: False | AG26: 17.2377 | AH26: 18.5451 | AI26: 1.002 | AJ26: 4425424896 | AK26: 4400193536 | AL26: 25231360 | AM26: 25231360 | AN26: 50463952 | AO26: 4.4254 | AP26: 5.015 | AQ26: 17.1938 | AR26: 12.2227 | AS26: 6.165 | AT26: 118.272 | AU26: 118.231 | AV26: 11.4585
A27: combined | B27: baseline | C27: TinyLlama/TinyLlama-1.1B-intermediate-step-1431k-3T | D27: bf16 | E27: 8 | F27: q_proj|k_proj|v_proj|o_proj|gate_proj|up_proj|down_proj | G27: all | H27: 32 | I27: 2048 | J27: amp_bf16 | K27: adam | L27: False | M27: 7 | AF27: True | AG27: OOM | AH27: OOM
A28: combined | B28: adam8bit | C28: TinyLlama/TinyLlama-1.1B-intermediate-step-1431k-3T | D28: bf16 | E28: 8 | F28: q_proj|k_proj|v_proj|o_proj|gate_proj|up_proj|down_proj | G28: all | H28: 32 | I28: 2048 | J28: amp_bf16 | K28: adam8bit | L28: False | M28: 7 | AF28: True | AG28: OOM | AH28: OOM
A29: combined | B29: checkpointing | C29: TinyLlama/TinyLlama-1.1B-intermediate-step-1431k-3T | D29: bf16 | E29: 8 | F29: q_proj|k_proj|v_proj|o_proj|gate_proj|up_proj|down_proj | G29: all | H29: 32 | I29: 2048 | J29: amp_bf16 | K29: adam | L29: True | M29: 7 | N29: 2048 | O29: 22 | P29: 32 | Q29: 4 | R29: 5632 | S29: 32000 | T29: 1100048384 | U29: 6307840 | V29: 22 | W29: 2.2001 | X29: 0.0252 | Y29: 0.0252 | Z29: 0.0505 | AA29: 0.0126 | AB29: 39.0238 | AC29: 41.2996 | AD29: 47.0996 | AE29: False | AF29: False | AG29: 38.1494 | AH29: 52.4561 | AI29: 0.924 | AJ29: 2225328128 | AK29: 2200096768 | AL29: 25231360 | AM29: 25231360 | AN29: 50463952 | AO29: 2.2274 | AP29: 7.1025 | AQ29: 34.7741 | AR29: 31.047 | AS29: 22.406 | AT29: 2166.757 | AU29: 2166.415 | AV29: 11.3199
A30: combined | B30: both | C30: TinyLlama/TinyLlama-1.1B-intermediate-step-1431k-3T | D30: bf16 | E30: 8 | F30: q_proj|k_proj|v_proj|o_proj|gate_proj|up_proj|down_proj | G30: all | H30: 32 | I30: 2048 | J30: amp_bf16 | K30: adam8bit | L30: True | M30: 7 | N30: 2048 | O30: 22 | P30: 32 | Q30: 4 | R30: 5632 | S30: 32000 | T30: 1100048384 | U30: 6307840 | V30: 22 | W30: 2.2001 | X30: 0.0252 | Y30: 0.0252 | Z30: 0.0126 | AA30: 0.0126 | AB30: 39.0238 | AC30: 41.2617 | AD30: 47.0617 | AE30: False | AF30: False | AG30: 38.1125 | AH30: 52.4015 | AI30: 0.924 | AJ30: 2225328128 | AK30: 2200096768 | AL30: 25231360 | AM30: 25231360 | AN30: 13891328 | AO30: 2.2274 | AP30: 7.0655 | AQ30: 34.7371 | AR30: 31.047 | AS30: 22.46 | AT30: 2178.593 | AU30: 2178.823 | AV30: 11.3202
A33: Source: runs/finetune-20260817-v3-finetune/results_finetune.csv. Formula match column below can be added post-hoc; the CSV already includes predicted/measured/error fields.

Sheet Notes & Sources
A1: Notes and sources
A3: What this workbook models | B3: Peak GPU memory for LoRA fine-tuning of a decoder-only transformer on ONE GPU. The frozen base is loaded at bf16/int8/int4 (your Step 1 choice), stored contiguously, and not backpropped through. Trainable LoRA adapters live in fp32. Only adapter parameters accumulate gradients and optimizer state. This is the setup Article 2 walks through and the exact configuration validated in the v3 sweep.
A4: This workbook is an overlay on Article 1's training workbook | B4: Four of the seven line items (adapter weights, gradients, optimizer state, autocast cache) are the same arithmetic as gpu-training-memory-sizing.xlsx applied to a much smaller trainable count. Two (frozen base, cuBLAS workspace) are new. Activations were rewritten for a Llama-family layer with GQA and SwiGLU. If a term does not appear on Article 1's tab, this document tells you why.
A5: Where the formulas come from | B5: benchmark/predictions_finetune.py in github.com/odog96/gpu-sizing-playbook. See the file for term-by-term derivations. Every constant used in the sheet appears there under a named function or a documented empirical constant.
A6: Where the measurements come from | B6: runs/finetune-20260817-v3-finetune/results_finetune.csv — a 25-configuration LoRA fine-tune sweep on a single NVIDIA H100 80GB, using TinyLlama-1.1B, varying batch size, sequence length, LoRA rank, adapter placement, base storage precision, optimizer, and checkpointing. Worst non-OOM error 8.3% (a checkpointed row); 21 of 21 non-OOM rows within +/-10%.
A7: How accurate is it | B7: Non-checkpointed rows: within +/-1% typical. Checkpointed rows: +2.9% / +8.3% / +8.3% (measured minus predicted). Two boundary configurations at the 79 GB cliff came in as OOM at ~82 GB reserved when the formula predicted ~78 GB -- reported honestly rather than tuned away, matching Article 1's precedent (its worst miss was 11.6% on checkpointing). All 23 non-OOM rows land within +/-10%.
A8: HIGH confidence — measured directly | B8: Frozen weights, adapter weights, adapter gradients, adapter optimizer state: summed directly from real tensors on the device via measured_param/grad/optimizer_bytes() in benchmark/memory_accounting.py.
A9: HIGH confidence — calculated and validated | B9: Activation formula, both non-checkpointed and checkpointed. The GQA and SwiGLU tensor counts were derived from HuggingFace LLaMA source and validated against the v3 sweep. cuBLAS workspace fit was derived from the same sweep (2-parameter linear fit; base_count 4.316 + per-adapter-layer 1.871).
A10: EMPIRICAL — cuBLAS zeroed under checkpointing | B10: Keeping the fitted cuBLAS count under checkpointing over-predicted three rows by 36-72%. Zeroing lands them at +2.9%/+8.3%/+8.3%. Physically justified: under gradient checkpointing the allocator repeatedly hits its cap during backward-recompute, forcing cuBLAS to release cached workspaces between segments. Same category of empirical claim as the CUDA context and fragmentation allowances.
A11: ESTIMATED — CUDA context and fragmentation | B11: Two allowances translate 'allocated' into 'will this actually fit'. PyTorch's memory API cannot see CUDA context. Fragmentation depends on allocator state. Values (0.6 / 1.2 / 5.2 GB) are held constant from Article 1's training sweep. Adjust in Advanced if you have better measurements.
A12: NOT VALIDATED — models above 1.1B | B12: The Model Presets tab includes LLaMA-2-7B, LLaMA-3-8B, Mistral-7B, LLaMA-2-13B, LLaMA-2-70B, but no measured evidence exists at these sizes. Formula extrapolation is clean (every term scales as it must from the TinyLlama base) but treat larger-model predictions as predictions.
A13: NOT VALIDATED — GQA-narrowed LoRA K/V adapters | B13: The adapter parameter count formula (2*r*d per target) approximates K and V LoRA as full-width. Real GQA-narrowed K/V adapters are (kv_heads/heads) narrower on the down-projection. The error is small (single-digit percent) and dwarfed by the frozen base.
A14: NOT MODELED — attention-probability materialization | B14: Assumes HuggingFace LLaMA dispatches SDPA / flash attention (the default). If you force eager attention, add batch * num_heads * seq_len^2 * activation_bytes to the activation term.
... A16: Units | B16: 1 GB = 1,000,000,000 bytes throughout, matching benchmark/predictions_finetune.py. Card capacities are advertised in GiB (1,073,741,824 bytes) and converted where they appear.
